Workbook
Name Selected_Date: #REF!

Sheet Export
A1: Cliente | B1: Sexo | C1: Contrato | D1: Estado | E1: Cosecha | F1: Mes envio recuperación | G1: Meses transcurridos | H1: Estatus recuperación | I1: Mes recuperación | J1: Plate | K1: Modelo | L1: Plataforma
A2: . RODRIGUEZ VICENTE | B2: Hombre | C2: 2519AF | D2: BAJA CALIFORNIA | E2: 04-2023 | F2: 04-2026 | G2: 36 | H2: Efectivo | I2: 04-2026 | J2: BGH042A | K2: ATTITUDE | L2: UBER
A3: . RODRIGUEZ VICENTE | B3: Hombre | C3: 6812AF | D3: BAJA CALIFORNIA | E3: 01-2026 | F3: 04-2026 | G3: 2 | H3: Efectivo | I3: 04-2026 | J3: CBY512A | K3: CHEVROLET AVEO | L3: DIDI
A4: ACEVES OSUNA FRANCISCO XAVIER | B4: Hombre | C4: 4990AF | D4: BAJA CALIFORNIA | E4: 06-2025 | F4: 03-2026 | G4: 9 | H4: Efectivo | I4: 03-2026 | J4: BYG580A | K4: CHEVROLET AVEO | L4: UBER
A5: ACOSTA CALDERON FERNANDO | B5: Hombre | C5: 3908AF | D5: CDMX Y AREA METROPOLITANA | E5: 10-2024 | F5: 10-2025 | G5: 11 | H5: Efectivo | I5: 11-2025 | J5: C34BPX | K5: TOYOTA AVANZA | L5: UBER
A6: ACOSTA MARTINEZ MIGUEL ANGEL | B6: Hombre | C6: 5944AF | D6: CDMX Y AREA METROPOLITANA | E6: 10-2025 | F6: 04-2026 | G6: 6 | H6: Pendiente | J6: 51G505 | K6: GAC AION S | L6: UBER
A7: ADAME SALINAS MICHEL ALBERTO | B7: Hombre | C7: 4523AF | D7: CDMX Y AREA METROPOLITANA | E7: 03-2025 | F7: 11-2025 | G7: 7 | H7: Efectivo | I7: 11-2025 | J7: 39G976 | K7: GAC AION S | L7: UBER
A8: ADAME TRUJILLO CHRISTIAN ARIEL | B8: Hombre | C8: 4399AF | D8: CDMX Y AREA METROPOLITANA | E8: 02-2025 | F8: 01-2026 | G8: 11 | H8: Efectivo | I8: 02-2026 | J8: 31G452 | K8: GAC AION S | L8: UBER
A9: AGAMA MEJIA ARTEMIO | B9: Hombre | C9: 5022AF | D9: CDMX Y AREA METROPOLITANA | E9: 06-2025 | F9: 03-2026 | G9: 9 | H9: Efectivo | I9: 03-2026 | J9: D96BRR | K9: CHEVROLET AVEO | L9: UBER
A10: AGUILAR GONZALEZ MARCO ANTONIO | B10: Hombre | C10: 5011AF | D10: CDMX Y AREA METROPOLITANA | E10: 06-2025 | F10: 03-2026 | G10: 10 | H10: Efectivo | I10: 04-2026 | J10: A84BMP | K10: CHEVROLET AVEO | L10: UBER
A11: AGUILAR GONZALEZ MIGUEL ANGEL | B11: Hombre | C11: 3889AF | D11: BAJA CALIFORNIA | E11: 10-2024 | F11: 06-2025 | G11: 8 | H11: Efectivo | I11: 07-2025 | J11: BSG377A | K11: CHEVROLET AVEO | L11: UBER
A12: AGUILAR LOPEZ ALFONSO | B12: Hombre | C12: 4270AF | D12: CDMX Y AREA METROPOLITANA | E12: 01-2025 | F12: 02-2026 | G12: 12 | H12: Pendiente | J12: 31G972 | K12: GAC AION S | L12: UBER
A13: AGUILAR REZA DIEGO ABRAHAM | B13: Hombre | C13: 6245AF | D13: CDMX Y AREA METROPOLITANA | E13: 11-2025 | F13: 04-2026 | G13: 5 | H13: Efectivo | I13: 05-2026 | J13: 62G480 | K13: BYD E5 | L13: UBER
A14: AGUILAR TREJO ADAN | B14: Hombre | C14: 5909AF | D14: BAJA CALIFORNIA | E14: 10-2025 | F14: 04-2026 | G14: 6 | H14: Efectivo | I14: 04-2026 | J14: CAJ035A | K14: CHEVROLET AVEO | L14: DIDI
A15: AGUILAR VERA OSCAR MAURICIO | B15: Hombre | C15: 4247AF | D15: JALISCO | E15: 01-2025 | F15: 11-2025 | G15: 9 | H15: Efectivo | I15: 03-2026 | J15: HWS688A | K15: CHEVROLET AVEO | L15: UBER
A16: AGUIRRE AVALOS CARLOS ALBERTO | B16: Hombre | C16: 4078AF | D16: JALISCO | E16: 12-2024 | F16: 01-2026 | G16: 13 | H16: Efectivo | I16: 01-2026 | J16: HWS689A | K16: CHEVROLET AVEO | L16: UBER
A17: AGUIRRE VELAZQUEZ MARIA ANTONIETA | B17: Mujer | C17: 6862AF | D17: CDMX Y AREA METROPOLITANA | E17: 01-2026 | F17: 02-2026 | G17: 1 | H17: Efectivo | I17: 02-2026 | J17: 29G385 | K17: GAC AION S | L17: UBER
A18: AGUIRRE ZAZUETA XIUMARA SERAIN | B18: Mujer | C18: 5875AF | D18: NUEVO LEON | E18: 10-2025 | F18: 02-2026 | G18: 4 | H18: Efectivo | I18: 02-2026 | J18: RXW058C | K18: CHEVROLET AVEO | L18: DIDI
A19: ALAMILLO CONTRERAS DANIEL | B19: Hombre | C19: 4082AF | D19: NUEVO LEON | E19: 12-2024 | F19: 04-2026 | G19: 16 | H19: Efectivo | I19: 04-2026 | J19: TFP758B | K19: CHEVROLET AVEO | L19: UBER
A20: ALANIS ARELLANO LUIS GERARDO | B20: Hombre | C20: 5589AF | D20: NUEVO LEON | E20: 08-2025 | F20: 04-2026 | G20: 7 | H20: Efectivo | I20: 04-2026 | J20: RWL277C | K20: TOYOTA AVANZA | L20: DIDI
A21: ALANIS SANTILLAN VICTOR MANUEL | B21: Hombre | C21: 4282AF | D21: CDMX Y AREA METROPOLITANA | E21: 02-2025 | F21: 04-2026 | G21: 14 | H21: Efectivo | I21: 04-2026 | J21: R25BRD | K21: CHEVROLET AVEO | L21: UBER
A22: ALARCON MARTINEZ ABRAHAM DANIEL | B22: Hombre | C22: 4771AF | D22: CDMX Y AREA METROPOLITANA | E22: 05-2025 | F22: 01-2026 | G22: 9 | H22: Efectivo | I22: 02-2026 | J22: E68BRR | K22: CHEVROLET AVEO | L22: DIDI
A23: ALATORRE MARQUEZ JORGE ALEJANDRO | B23: Hombre | C23: 2944AF | D23: JALISCO | E23: 01-2024 | F23: 03-2026 | G23: 26 | H23: Cancelado | J23: HSJ725A | K23: CHEVROLET AVEO | L23: UBER
A24: ALBA PARAMO NOE | B24: Hombre | C24: 5625AF | D24: CDMX Y AREA METROPOLITANA | E24: 08-2025 | F24: 12-2025 | G24: 3 | H24: Pendiente | J24: 48G241 | K24: BYD MINIDOLPHIN | L24: DIDI
A25: ALCALA NOVEROLA MARIO JONATHAN | B25: Hombre | C25: 5784AF | D25: CDMX Y AREA METROPOLITANA | E25: 09-2025 | F25: 02-2026 | G25: 4 | H25: Efectivo | I25: 02-2026 | J25: 10K823 | K25: BYD MINIDOLPHIN | L25: UBER
A26: ALCANTAR SILVA ARMANDO | B26: Hombre | C26: 2745AF | D26: BAJA CALIFORNIA | E26: 09-2023 | F26: 06-2025 | G26: 21 | H26: Efectivo | I26: 06-2025 | J26: BJX359A | K26: CHEVROLET AVEO | L26: UBER
A27: ALCANTARA SANCHEZ ENRIQUE ABRAHAM | B27: Hombre | C27: 5800AF | D27: CDMX Y AREA METROPOLITANA | E27: 09-2025 | F27: 05-2026 | G27: 7 | H27: Efectivo | I27: 05-2026 | J27: 10K840 | K27: BYD MINIDOLPHIN | L27: UBER
A28: ALCANTARA SEGURA JUAN | B28: Hombre | C28: 4370AF | D28: CDMX Y AREA METROPOLITANA | E28: 02-2025 | F28: 06-2025 | G28: 3 | H28: Efectivo | I28: 06-2025 | J28: 19G586 | K28: BYD D1 | L28: UBER
A29: ALCIBAR PEÑA DANIEL | B29: Hombre | C29: 4368AF | D29: CDMX Y AREA METROPOLITANA | E29: 02-2025 | F29: 04-2025 | G29: 2 | H29: Efectivo | I29: 05-2025 | J29: 31G788 | K29: GAC AION S | L29: DIDI
A30: ALDANA RUIZ ISRAEL | B30: Hombre | C30: 5409AF | D30: CDMX Y AREA METROPOLITANA | E30: 07-2025 | F30: 03-2026 | G30: 8 | H30: Efectivo | I30: 03-2026 | J30: 48G145 | K30: BYD MINIDOLPHIN | L30: DIDI
A31: ALDAPE BARCENAS ILSE ABIGAIL | B31: Mujer | C31: 5889AF | D31: NUEVO LEON | E31: 10-2025 | F31: 03-2026 | G31: 6 | H31: Pendiente | J31: RXC615C | K31: TOYOTA AVANZA | L31: UBER
A32: ALEJANDRE GABRIEL DIEGO | B32: Hombre | C32: 6382AF | D32: NUEVO LEON | E32: 11-2025 | F32: 04-2026 | G32: 4 | H32: Pendiente | J32: RZB056C | K32: CHEVROLET AVEO | L32: DIDI
A33: ALEMAN CONTRERAS MANUEL ALEJANDRO | B33: Hombre | C33: 6440AF | D33: CDMX Y AREA METROPOLITANA | E33: 12-2025 | F33: 02-2026 | G33: 2 | H33: Pendiente | J33: 51G818 | K33: BYD MINIDOLPHIN | L33: UBER
A34: ALFARO MARTINEZ LUIS ENRIQUE | B34: Hombre | C34: 3767AF | D34: CDMX Y AREA METROPOLITANA | E34: 09-2024 | F34: 04-2025 | G34: 6 | H34: Efectivo | I34: 04-2025 | J34: 05G231 | K34: BYD D1 | L34: UBER
A35: ALMANZA VITE OCTAVIO DAMIAN | B35: Hombre | C35: 4506AF | D35: CDMX Y AREA METROPOLITANA | E35: 03-2025 | F35: 06-2025 | G35: 2 | H35: Efectivo | I35: 06-2025 | J35: Y47BNL | K35: CHEVROLET AVEO | L35: UBER
A36: ALONSO ALONSO ROSA CARMEN | B36: Mujer | C36: 4904AF | D36: NUEVO LEON | E36: 05-2025 | F36: 07-2025 | G36: 2 | H36: Efectivo | I36: 08-2025 | J36: RUB750C | K36: TOYOTA AVANZA | L36: DIDI
A37: ALONSO DEL ANGEL ALEJANDRO | B37: Hombre | C37: 4167AF | D37: CDMX Y AREA METROPOLITANA | E37: 12-2024 | F37: 03-2026 | G37: 15 | H37: Efectivo | I37: 04-2026 | J37: 19G518 | K37: BYD D1 | L37: UBER
A38: ALONSO GUERRA LUIS ALONSO | B38: Hombre | C38: 5550AF | D38: NUEVO LEON | E38: 08-2025 | F38: 02-2026 | G38: 6 | H38: Cancelado | J38: RVX593C | K38: CHEVROLET AVEO | L38: UBER
A39: ALONSO ROJAS LUIS ENRIQUE | B39: Hombre | C39: 3032AF | D39: CDMX Y AREA METROPOLITANA | E39: 02-2024 | F39: 08-2025 | G39: 18 | H39: Cancelado | J39: T14BNL | K39: CHEVROLET AVEO | L39: UBER
A40: ALTAMIRANO FLORES ANGEL EDUARDO | B40: Hombre | C40: 5058AF | D40: CDMX Y AREA METROPOLITANA | E40: 06-2025 | F40: 11-2025 | G40: 5 | H40: Pendiente | J40: B87BPD | K40: CHEVROLET AVEO | L40: DIDI
...

Sheet Perfil Recuperados
B2: PERFIL DE AUTOS RECUPERADOS
B3: Análisis descriptivo · 978 unidades efectivamente recuperadas
B5: Total recuperados | C5: Tiempo prom. (meses) | D5: Tiempo mediano (meses) | E5: Tiempo máx (meses) | G5: HALLAZGOS CLAVE
B6: =COUNTA('recuperación efectiva'!A2:A979) -> 978 | C6: =AVERAGE('recuperación efectiva'!H2:H979) -> 8.7944785 | D6: =MEDIAN('recuperación efectiva'!H2:H979) -> 7 | E6: =MAX('recuperación efectiva'!H2:H979) -> 37 | G6: Plataforma: UBER concentra el 75% de las recuperaciones (737 vs 241 de DIDI), pero DIDI recupera más rápido en promedio (5.6 vs 9.9 meses).
G7: Sexo: 98% hombres (958) vs 2% mujeres (20). El sexo no es un factor discriminante.
B8: 1. POR PLATAFORMA | G8: Estado: CDMX y área metropolitana domina con 74% (727 unidades). Querétaro tiene los tiempos más largos (25.9 meses promedio).
B9: Plataforma | C9: Recuperados | D9: % del total | E9: Tiempo prom. (meses) | G9: Año de cosecha: factor más relevante. Cosechas 2025 se recuperan en 5.9 meses; cosechas 2022 tardan 31.5 meses. A mayor antigüedad, mayor tiempo.
B10: UBER | C10: =COUNTIF('recuperación efectiva'!M:M,B10) -> 0 | D10: =C10/$B$6 -> 0 | E10: =AVERAGEIF('recuperación efectiva'!M:M,B10,'recuperación efectiva'!H:H) -> #DIV/0!
B11: DIDI | C11: =COUNTIF('recuperación efectiva'!M:M,B11) -> 0 | D11: =C11/$B$6 -> 0 | E11: =AVERAGEIF('recuperación efectiva'!M:M,B11,'recuperación efectiva'!H:H) -> #DIV/0!
B13: 2. POR SEXO
B14: Sexo | C14: Recuperados | D14: % del total | E14: Tiempo prom. (meses)
B15: Hombre | C15: =COUNTIF('recuperación efectiva'!B:B,B15) -> 958 | D15: =C15/$B$6 -> 0.9795501 | E15: =AVERAGEIF('recuperación efectiva'!B:B,B15,'recuperación efectiva'!H:H) -> 8.8350731
B16: Mujer | C16: =COUNTIF('recuperación efectiva'!B:B,B16) -> 20 | D16: =C16/$B$6 -> 0.020449898 | E16: =AVERAGEIF('recuperación efectiva'!B:B,B16,'recuperación efectiva'!H:H) -> 6.85
B18: 3. POR ESTADO
B19: Estado | C19: Recuperados | D19: % del total | E19: Tiempo prom. (meses)
B20: CDMX Y AREA METROPOLITANA | C20: =COUNTIF('recuperación efectiva'!D:D,B20) -> 727 | D20: =C20/$B$6 -> 0.74335378 | E20: =AVERAGEIF('recuperación efectiva'!D:D,B20,'recuperación efectiva'!H:H) -> 8.3713893
B21: BAJA CALIFORNIA | C21: =COUNTIF('recuperación efectiva'!D:D,B21) -> 118 | D21: =C21/$B$6 -> 0.1206544 | E21: =AVERAGEIF('recuperación efectiva'!D:D,B21,'recuperación efectiva'!H:H) -> 9.4915254
B22: NUEVO LEON | C22: =COUNTIF('recuperación efectiva'!D:D,B22) -> 75 | D22: =C22/$B$6 -> 0.076687117 | E22: =AVERAGEIF('recuperación efectiva'!D:D,B22,'recuperación efectiva'!H:H) -> 7.2533333
B23: JALISCO | C23: =COUNTIF('recuperación efectiva'!D:D,B23) -> 50 | D23: =C23/$B$6 -> 0.051124744 | E23: =AVERAGEIF('recuperación efectiva'!D:D,B23,'recuperación efectiva'!H:H) -> 12.88
B24: QUERETARO | C24: =COUNTIF('recuperación efectiva'!D:D,B24) -> 8 | D24: =C24/$B$6 -> 0.0081799591 | E24: =AVERAGEIF('recuperación efectiva'!D:D,B24,'recuperación efectiva'!H:H) -> 25.875
B25: JALISCO
B26: 4. POR AÑO DE COSECHA
B27: Año | C27: Recuperados | D27: % del total | E27: Tiempo prom. (meses)
B28: 2022 | C28: =COUNTIF('recuperación efectiva'!F:F,B28) -> 12 | D28: =C28/$B$6 -> 0.012269939 | E28: =AVERAGEIF('recuperación efectiva'!F:F,B28,'recuperación efectiva'!H:H) -> 31.5
B29: 2023 | C29: =COUNTIF('recuperación efectiva'!F:F,B29) -> 48 | D29: =C29/$B$6 -> 0.049079755 | E29: =AVERAGEIF('recuperación efectiva'!F:F,B29,'recuperación efectiva'!H:H) -> 23.708333
B30: 2024 | C30: =COUNTIF('recuperación efectiva'!F:F,B30) -> 287 | D30: =C30/$B$6 -> 0.29345603 | E30: =AVERAGEIF('recuperación efectiva'!F:F,B30,'recuperación efectiva'!H:H) -> 11.930314
B31: 2025 | C31: =COUNTIF('recuperación efectiva'!F:F,B31) -> 612 | D31: =C31/$B$6 -> 0.62576687 | E31: =AVERAGEIF('recuperación efectiva'!F:F,B31,'recuperación efectiva'!H:H) -> 5.9101307
B32: 2026 | C32: =COUNTIF('recuperación efectiva'!F:F,B32) -> 19 | D32: =C32/$B$6 -> 0.019427403 | E32: =AVERAGEIF('recuperación efectiva'!F:F,B32,'recuperación efectiva'!H:H) -> 2.3157895
B34: 5. POR MODELO
B35: Modelo | C35: Recuperados | D35: % del total | E35: Tiempo prom. (meses)
B36: CHEVROLET AVEO | C36: =COUNTIF('recuperación efectiva'!L:L,B36) -> 0 | D36: =C36/$B$6 -> 0 | E36: =AVERAGEIF('recuperación efectiva'!L:L,B36,'recuperación efectiva'!H:H) -> #DIV/0!
B37: BYD D1 | C37: =COUNTIF('recuperación efectiva'!L:L,B37) -> 0 | D37: =C37/$B$6 -> 0 | E37: =AVERAGEIF('recuperación efectiva'!L:L,B37,'recuperación efectiva'!H:H) -> #DIV/0!
B38: GAC AION S | C38: =COUNTIF('recuperación efectiva'!L:L,B38) -> 0 | D38: =C38/$B$6 -> 0 | E38: =AVERAGEIF('recuperación efectiva'!L:L,B38,'recuperación efectiva'!H:H) -> #DIV/0!
B39: BYD MINIDOLPHIN | C39: =COUNTIF('recuperación efectiva'!L:L,B39) -> 0 | D39: =C39/$B$6 -> 0 | E39: =AVERAGEIF('recuperación efectiva'!L:L,B39,'recuperación efectiva'!H:H) -> #DIV/0!
B40: TOYOTA AVANZA | C40: =COUNTIF('recuperación efectiva'!L:L,B40) -> 0 | D40: =C40/$B$6 -> 0 | E40: =AVERAGEIF('recuperación efectiva'!L:L,B40,'recuperación efectiva'!H:H) -> #DIV/0!
B41: BYD E5 | C41: =COUNTIF('recuperación efectiva'!L:L,B41) -> 0 | D41: =C41/$B$6 -> 0 | E41: =AVERAGEIF('recuperación efectiva'!L:L,B41,'recuperación efectiva'!H:H) -> #DIV/0!
B42: SUZUKI ERTIGA | C42: =COUNTIF('recuperación efectiva'!L:L,B42) -> 0 | D42: =C42/$B$6 -> 0 | E42: =AVERAGEIF('recuperación efectiva'!L:L,B42,'recuperación efectiva'!H:H) -> #DIV/0!
B43: ATTITUDE | C43: =COUNTIF('recuperación efectiva'!L:L,B43) -> 0 | D43: =C43/$B$6 -> 0 | E43: =AVERAGEIF('recuperación efectiva'!L:L,B43,'recuperación efectiva'!H:H) -> #DIV/0!
B44: ONIX | C44: =COUNTIF('recuperación efectiva'!L:L,B44) -> 0 | D44: =C44/$B$6 -> 0 | E44: =AVERAGEIF('recuperación efectiva'!L:L,B44,'recuperación efectiva'!H:H) -> #DIV/0!
B45: IGNIS | C45: =COUNTIF('recuperación efectiva'!L:L,B45) -> 0 | D45: =C45/$B$6 -> 0 | E45: =AVERAGEIF('recuperación efectiva'!L:L,B45,'recuperación efectiva'!H:H) -> #DIV/0!
...

Sheet recuperación efectiva
A1: Cliente | B1: Sexo | C1: Contrato | D1: Estado | E1: Cosecha | F1: Año Cosecha | G1: Mes envio recuperación | H1: Meses transcurridos | I1: Estatus recuperación | J1: Mes recuperación | K1: Meses transcurridos tras recuperación efectiva | L1: Plate | M1: Modelo | N1: Plataforma
A2: . RODRIGUEZ VICENTE | B2: Hombre | C2: 2519AF | D2: BAJA CALIFORNIA | E2: 04-2023 | F2: =+YEAR(Tabla2[[#This Row],[Cosecha]]) -> 2023 | G2: 04-2026 | H2: =(YEAR(G2)-YEAR(E2))*12+(MONTH(G2)-MONTH(E2)) -> 36 | I2: Efectivo | J2: 04-2026 | K2: =(YEAR(J2)-YEAR(E2))*12+(MONTH(J2)-MONTH(E2)) -> 36 | L2: BGH042A | M2: ATTITUDE | N2: UBER
A3: . RODRIGUEZ VICENTE | B3: Hombre | C3: 6812AF | D3: BAJA CALIFORNIA | E3: 01-2026 | F3: =+YEAR(Tabla2[[#This Row],[Cosecha]]) -> 2026 | G3: 04-2026 | H3: =(YEAR(G3)-YEAR(E3))*12+(MONTH(G3)-MONTH(E3)) -> 3 | I3: Efectivo | J3: 04-2026 | K3: =(YEAR(J3)-YEAR(E3))*12+(MONTH(J3)-MONTH(E3)) -> 3 | L3: CBY512A | M3: CHEVROLET AVEO | N3: DIDI | P3: 📊 Distribución por Sexo
A4: ACEVES OSUNA FRANCISCO XAVIER | B4: Hombre | C4: 4990AF | D4: BAJA CALIFORNIA | E4: 06-2025 | F4: =+YEAR(Tabla2[[#This Row],[Cosecha]]) -> 2025 | G4: 03-2026 | H4: =(YEAR(G4)-YEAR(E4))*12+(MONTH(G4)-MONTH(E4)) -> 9 | I4: Efectivo | J4: 03-2026 | K4: =(YEAR(J4)-YEAR(E4))*12+(MONTH(J4)-MONTH(E4)) -> 9 | L4: BYG580A | M4: CHEVROLET AVEO | N4: UBER | P4: Sexo | Q4: Cantidad | R4: Avg. Meses transcurridos
A5: ACOSTA CALDERON FERNANDO | B5: Hombre | C5: 3908AF | D5: CDMX Y AREA METROPOLITANA | E5: 10-2024 | F5: =+YEAR(Tabla2[[#This Row],[Cosecha]]) -> 2024 | G5: 10-2025 | H5: =(YEAR(G5)-YEAR(E5))*12+(MONTH(G5)-MONTH(E5)) -> 12 | I5: Efectivo | J5: 11-2025 | K5: =(YEAR(J5)-YEAR(E5))*12+(MONTH(J5)-MONTH(E5)) -> 13 | L5: C34BPX | M5: TOYOTA AVANZA | N5: UBER | P5: Hombre | Q5: =COUNTIF(B:B,"Hombre") -> 958 | R5: =+ROUND(AVERAGEIF(B:B,Tabla3[[#This Row],[Sexo]],H:H),0) -> 9
A6: ADAME SALINAS MICHEL ALBERTO | B6: Hombre | C6: 4523AF | D6: CDMX Y AREA METROPOLITANA | E6: 03-2025 | F6: =+YEAR(Tabla2[[#This Row],[Cosecha]]) -> 2025 | G6: 11-2025 | H6: =(YEAR(G6)-YEAR(E6))*12+(MONTH(G6)-MONTH(E6)) -> 8 | I6: Efectivo | J6: 11-2025 | K6: =(YEAR(J6)-YEAR(E6))*12+(MONTH(J6)-MONTH(E6)) -> 8 | L6: 39G976 | M6: GAC AION S | N6: UBER | P6: Mujer | Q6: =COUNTIF(B:B,"Mujer") -> 20 | R6: =+ROUND(AVERAGEIF(B:B,Tabla3[[#This Row],[Sexo]],H:H),0) -> 7
A7: ADAME TRUJILLO CHRISTIAN ARIEL | B7: Hombre | C7: 4399AF | D7: CDMX Y AREA METROPOLITANA | E7: 02-2025 | F7: =+YEAR(Tabla2[[#This Row],[Cosecha]]) -> 2025 | G7: 01-2026 | H7: =(YEAR(G7)-YEAR(E7))*12+(MONTH(G7)-MONTH(E7)) -> 11 | I7: Efectivo | J7: 02-2026 | K7: =(YEAR(J7)-YEAR(E7))*12+(MONTH(J7)-MONTH(E7)) -> 12 | L7: 31G452 | M7: GAC AION S | N7: UBER
A8: AGAMA MEJIA ARTEMIO | B8: Hombre | C8: 5022AF | D8: CDMX Y AREA METROPOLITANA | E8: 06-2025 | F8: =+YEAR(Tabla2[[#This Row],[Cosecha]]) -> 2025 | G8: 03-2026 | H8: =(YEAR(G8)-YEAR(E8))*12+(MONTH(G8)-MONTH(E8)) -> 9 | I8: Efectivo | J8: 03-2026 | K8: =(YEAR(J8)-YEAR(E8))*12+(MONTH(J8)-MONTH(E8)) -> 9 | L8: D96BRR | M8: CHEVROLET AVEO | N8: UBER
A9: AGUILAR GONZALEZ MARCO ANTONIO | B9: Hombre | C9: 5011AF | D9: CDMX Y AREA METROPOLITANA | E9: 06-2025 | F9: =+YEAR(Tabla2[[#This Row],[Cosecha]]) -> 2025 | G9: 03-2026 | H9: =(YEAR(G9)-YEAR(E9))*12+(MONTH(G9)-MONTH(E9)) -> 9 | I9: Efectivo | J9: 04-2026 | K9: =(YEAR(J9)-YEAR(E9))*12+(MONTH(J9)-MONTH(E9)) -> 10 | L9: A84BMP | M9: CHEVROLET AVEO | N9: UBER
A10: AGUILAR GONZALEZ MIGUEL ANGEL | B10: Hombre | C10: 3889AF | D10: BAJA CALIFORNIA | E10: 10-2024 | F10: =+YEAR(Tabla2[[#This Row],[Cosecha]]) -> 2024 | G10: 06-2025 | H10: =(YEAR(G10)-YEAR(E10))*12+(MONTH(G10)-MONTH(E10)) -> 8 | I10: Efectivo | J10: 07-2025 | K10: =(YEAR(J10)-YEAR(E10))*12+(MONTH(J10)-MONTH(E10)) -> 9 | L10: BSG377A | M10: CHEVROLET AVEO | N10: UBER
A11: AGUILAR REZA DIEGO ABRAHAM | B11: Hombre | C11: 6245AF | D11: CDMX Y AREA METROPOLITANA | E11: 11-2025 | F11: =+YEAR(Tabla2[[#This Row],[Cosecha]]) -> 2025 | G11: 04-2026 | H11: =(YEAR(G11)-YEAR(E11))*12+(MONTH(G11)-MONTH(E11)) -> 5 | I11: Efectivo | J11: 05-2026 | K11: =(YEAR(J11)-YEAR(E11))*12+(MONTH(J11)-MONTH(E11)) -> 6 | L11: 62G480 | M11: BYD E5 | N11: UBER
A12: AGUILAR TREJO ADAN | B12: Hombre | C12: 5909AF | D12: BAJA CALIFORNIA | E12: 10-2025 | F12: =+YEAR(Tabla2[[#This Row],[Cosecha]]) -> 2025 | G12: 04-2026 | H12: =(YEAR(G12)-YEAR(E12))*12+(MONTH(G12)-MONTH(E12)) -> 6 | I12: Efectivo | J12: 04-2026 | K12: =(YEAR(J12)-YEAR(E12))*12+(MONTH(J12)-MONTH(E12)) -> 6 | L12: CAJ035A | M12: CHEVROLET AVEO | N12: DIDI
A13: AGUILAR VERA OSCAR MAURICIO | B13: Hombre | C13: 4247AF | D13: JALISCO | E13: 01-2025 | F13: =+YEAR(Tabla2[[#This Row],[Cosecha]]) -> 2025 | G13: 11-2025 | H13: =(YEAR(G13)-YEAR(E13))*12+(MONTH(G13)-MONTH(E13)) -> 10 | I13: Efectivo | J13: 03-2026 | K13: =(YEAR(J13)-YEAR(E13))*12+(MONTH(J13)-MONTH(E13)) -> 14 | L13: HWS688A | M13: CHEVROLET AVEO | N13: UBER
A14: AGUIRRE AVALOS CARLOS ALBERTO | B14: Hombre | C14: 4078AF | D14: JALISCO | E14: 12-2024 | F14: =+YEAR(Tabla2[[#This Row],[Cosecha]]) -> 2024 | G14: 01-2026 | H14: =(YEAR(G14)-YEAR(E14))*12+(MONTH(G14)-MONTH(E14)) -> 13 | I14: Efectivo | J14: 01-2026 | K14: =(YEAR(J14)-YEAR(E14))*12+(MONTH(J14)-MONTH(E14)) -> 13 | L14: HWS689A | M14: CHEVROLET AVEO | N14: UBER
A15: AGUIRRE VELAZQUEZ MARIA ANTONIETA | B15: Mujer | C15: 6862AF | D15: CDMX Y AREA METROPOLITANA | E15: 01-2026 | F15: =+YEAR(Tabla2[[#This Row],[Cosecha]]) -> 2026 | G15: 02-2026 | H15: =(YEAR(G15)-YEAR(E15))*12+(MONTH(G15)-MONTH(E15)) -> 1 | I15: Efectivo | J15: 02-2026 | K15: =(YEAR(J15)-YEAR(E15))*12+(MONTH(J15)-MONTH(E15)) -> 1 | L15: 29G385 | M15: GAC AION S | N15: UBER | P15: 📍 Distribución por Estado
A16: AGUIRRE ZAZUETA XIUMARA SERAIN | B16: Mujer | C16: 5875AF | D16: NUEVO LEON | E16: 10-2025 | F16: =+YEAR(Tabla2[[#This Row],[Cosecha]]) -> 2025 | G16: 02-2026 | H16: =(YEAR(G16)-YEAR(E16))*12+(MONTH(G16)-MONTH(E16)) -> 4 | I16: Efectivo | J16: 02-2026 | K16: =(YEAR(J16)-YEAR(E16))*12+(MONTH(J16)-MONTH(E16)) -> 4 | L16: RXW058C | M16: CHEVROLET AVEO | N16: DIDI | P16: Estado | Q16: Cantidad | R16: Avg. Meses transcurridos
A17: ALAMILLO CONTRERAS DANIEL | B17: Hombre | C17: 4082AF | D17: NUEVO LEON | E17: 12-2024 | F17: =+YEAR(Tabla2[[#This Row],[Cosecha]]) -> 2024 | G17: 04-2026 | H17: =(YEAR(G17)-YEAR(E17))*12+(MONTH(G17)-MONTH(E17)) -> 16 | I17: Efectivo | J17: 04-2026 | K17: =(YEAR(J17)-YEAR(E17))*12+(MONTH(J17)-MONTH(E17)) -> 16 | L17: TFP758B | M17: CHEVROLET AVEO | N17: UBER | P17: QUERETARO | Q17: =COUNTIF(D:D,Tabla35[[#This Row],[Estado]]) -> 8 | R17: =+ROUND(AVERAGEIF(D:D,Tabla35[[#This Row],[Estado]],H:H),0) -> 26
A18: ALANIS ARELLANO LUIS GERARDO | B18: Hombre | C18: 5589AF | D18: NUEVO LEON | E18: 08-2025 | F18: =+YEAR(Tabla2[[#This Row],[Cosecha]]) -> 2025 | G18: 04-2026 | H18: =(YEAR(G18)-YEAR(E18))*12+(MONTH(G18)-MONTH(E18)) -> 8 | I18: Efectivo | J18: 04-2026 | K18: =(YEAR(J18)-YEAR(E18))*12+(MONTH(J18)-MONTH(E18)) -> 8 | L18: RWL277C | M18: TOYOTA AVANZA | N18: DIDI | P18: JALISCO | Q18: =COUNTIF(D:D,Tabla35[[#This Row],[Estado]]) -> 50 | R18: =+ROUND(AVERAGEIF(D:D,Tabla35[[#This Row],[Estado]],H:H),0) -> 13
A19: ALANIS SANTILLAN VICTOR MANUEL | B19: Hombre | C19: 4282AF | D19: CDMX Y AREA METROPOLITANA | E19: 02-2025 | F19: =+YEAR(Tabla2[[#This Row],[Cosecha]]) -> 2025 | G19: 04-2026 | H19: =(YEAR(G19)-YEAR(E19))*12+(MONTH(G19)-MONTH(E19)) -> 14 | I19: Efectivo | J19: 04-2026 | K19: =(YEAR(J19)-YEAR(E19))*12+(MONTH(J19)-MONTH(E19)) -> 14 | L19: R25BRD | M19: CHEVROLET AVEO | N19: UBER | P19: BAJA CALIFORNIA | Q19: =COUNTIF(D:D,Tabla35[[#This Row],[Estado]]) -> 118 | R19: =+ROUND(AVERAGEIF(D:D,Tabla35[[#This Row],[Estado]],H:H),0) -> 9
A20: ALARCON MARTINEZ ABRAHAM DANIEL | B20: Hombre | C20: 4771AF | D20: CDMX Y AREA METROPOLITANA | E20: 05-2025 | F20: =+YEAR(Tabla2[[#This Row],[Cosecha]]) -> 2025 | G20: 01-2026 | H20: =(YEAR(G20)-YEAR(E20))*12+(MONTH(G20)-MONTH(E20)) -> 8 | I20: Efectivo | J20: 02-2026 | K20: =(YEAR(J20)-YEAR(E20))*12+(MONTH(J20)-MONTH(E20)) -> 9 | L20: E68BRR | M20: CHEVROLET AVEO | N20: DIDI | P20: CDMX Y AREA METROPOLITANA | Q20: =COUNTIF(D:D,Tabla35[[#This Row],[Estado]]) -> 727 | R20: =+ROUND(AVERAGEIF(D:D,Tabla35[[#This Row],[Estado]],H:H),0) -> 8
A21: ALCALA NOVEROLA MARIO JONATHAN | B21: Hombre | C21: 5784AF | D21: CDMX Y AREA METROPOLITANA | E21: 09-2025 | F21: =+YEAR(Tabla2[[#This Row],[Cosecha]]) -> 2025 | G21: 02-2026 | H21: =(YEAR(G21)-YEAR(E21))*12+(MONTH(G21)-MONTH(E21)) -> 5 | I21: Efectivo | J21: 02-2026 | K21: =(YEAR(J21)-YEAR(E21))*12+(MONTH(J21)-MONTH(E21)) -> 5 | L21: 10K823 | M21: BYD MINIDOLPHIN | N21: UBER | P21: NUEVO LEON | Q21: =COUNTIF(D:D,Tabla35[[#This Row],[Estado]]) -> 75 | R21: =+ROUND(AVERAGEIF(D:D,Tabla35[[#This Row],[Estado]],H:H),0) -> 7
A22: ALCANTAR SILVA ARMANDO | B22: Hombre | C22: 2745AF | D22: BAJA CALIFORNIA | E22: 09-2023 | F22: =+YEAR(Tabla2[[#This Row],[Cosecha]]) -> 2023 | G22: 06-2025 | H22: =(YEAR(G22)-YEAR(E22))*12+(MONTH(G22)-MONTH(E22)) -> 21 | I22: Efectivo | J22: 06-2025 | K22: =(YEAR(J22)-YEAR(E22))*12+(MONTH(J22)-MONTH(E22)) -> 21 | L22: BJX359A | M22: CHEVROLET AVEO | N22: UBER
A23: ALCANTARA SANCHEZ ENRIQUE ABRAHAM | B23: Hombre | C23: 5800AF | D23: CDMX Y AREA METROPOLITANA | E23: 09-2025 | F23: =+YEAR(Tabla2[[#This Row],[Cosecha]]) -> 2025 | G23: 05-2026 | H23: =(YEAR(G23)-YEAR(E23))*12+(MONTH(G23)-MONTH(E23)) -> 8 | I23: Efectivo | J23: 05-2026 | K23: =(YEAR(J23)-YEAR(E23))*12+(MONTH(J23)-MONTH(E23)) -> 8 | L23: 10K840 | M23: BYD MINIDOLPHIN | N23: UBER
A24: ALCANTARA SEGURA JUAN | B24: Hombre | C24: 4370AF | D24: CDMX Y AREA METROPOLITANA | E24: 02-2025 | F24: =+YEAR(Tabla2[[#This Row],[Cosecha]]) -> 2025 | G24: 06-2025 | H24: =(YEAR(G24)-YEAR(E24))*12+(MONTH(G24)-MONTH(E24)) -> 4 | I24: Efectivo | J24: 06-2025 | K24: =(YEAR(J24)-YEAR(E24))*12+(MONTH(J24)-MONTH(E24)) -> 4 | L24: 19G586 | M24: BYD D1 | N24: UBER
A25: ALCIBAR PEÑA DANIEL | B25: Hombre | C25: 4368AF | D25: CDMX Y AREA METROPOLITANA | E25: 02-2025 | F25: =+YEAR(Tabla2[[#This Row],[Cosecha]]) -> 2025 | G25: 04-2025 | H25: =(YEAR(G25)-YEAR(E25))*12+(MONTH(G25)-MONTH(E25)) -> 2 | I25: Efectivo | J25: 05-2025 | K25: =(YEAR(J25)-YEAR(E25))*12+(MONTH(J25)-MONTH(E25)) -> 3 | L25: 31G788 | M25: GAC AION S | N25: DIDI
A26: ALDANA RUIZ ISRAEL | B26: Hombre | C26: 5409AF | D26: CDMX Y AREA METROPOLITANA | E26: 07-2025 | F26: =+YEAR(Tabla2[[#This Row],[Cosecha]]) -> 2025 | G26: 03-2026 | H26: =(YEAR(G26)-YEAR(E26))*12+(MONTH(G26)-MONTH(E26)) -> 8 | I26: Efectivo | J26: 03-2026 | K26: =(YEAR(J26)-YEAR(E26))*12+(MONTH(J26)-MONTH(E26)) -> 8 | L26: 48G145 | M26: BYD MINIDOLPHIN | N26: DIDI
A27: ALFARO MARTINEZ LUIS ENRIQUE | B27: Hombre | C27: 3767AF | D27: CDMX Y AREA METROPOLITANA | E27: 09-2024 | F27: =+YEAR(Tabla2[[#This Row],[Cosecha]]) -> 2024 | G27: 04-2025 | H27: =(YEAR(G27)-YEAR(E27))*12+(MONTH(G27)-MONTH(E27)) -> 7 | I27: Efectivo | J27: 04-2025 | K27: =(YEAR(J27)-YEAR(E27))*12+(MONTH(J27)-MONTH(E27)) -> 7 | L27: 05G231 | M27: BYD D1 | N27: UBER
A28: ALMANZA VITE OCTAVIO DAMIAN | B28: Hombre | C28: 4506AF | D28: CDMX Y AREA METROPOLITANA | E28: 03-2025 | F28: =+YEAR(Tabla2[[#This Row],[Cosecha]]) -> 2025 | G28: 06-2025 | H28: =(YEAR(G28)-YEAR(E28))*12+(MONTH(G28)-MONTH(E28)) -> 3 | I28: Efectivo | J28: 06-2025 | K28: =(YEAR(J28)-YEAR(E28))*12+(MONTH(J28)-MONTH(E28)) -> 3 | L28: Y47BNL | M28: CHEVROLET AVEO | N28: UBER
A29: ALONSO ALONSO ROSA CARMEN | B29: Mujer | C29: 4904AF | D29: NUEVO LEON | E29: 05-2025 | F29: =+YEAR(Tabla2[[#This Row],[Cosecha]]) -> 2025 | G29: 07-2025 | H29: =(YEAR(G29)-YEAR(E29))*12+(MONTH(G29)-MONTH(E29)) -> 2 | I29: Efectivo | J29: 08-2025 | K29: =(YEAR(J29)-YEAR(E29))*12+(MONTH(J29)-MONTH(E29)) -> 3 | L29: RUB750C | M29: TOYOTA AVANZA | N29: DIDI
A30: ALONSO DEL ANGEL ALEJANDRO | B30: Hombre | C30: 4167AF | D30: CDMX Y AREA METROPOLITANA | E30: 12-2024 | F30: =+YEAR(Tabla2[[#This Row],[Cosecha]]) -> 2024 | G30: 03-2026 | H30: =(YEAR(G30)-YEAR(E30))*12+(MONTH(G30)-MONTH(E30)) -> 15 | I30: Efectivo | J30: 04-2026 | K30: =(YEAR(J30)-YEAR(E30))*12+(MONTH(J30)-MONTH(E30)) -> 16 | L30: 19G518 | M30: BYD D1 | N30: UBER | P30: 📅 Meses Transcurridos por Año
A31: ALVA RAMIREZ GABRIEL ALEJANDRO | B31: Hombre | C31: 6507AF | D31: JALISCO | E31: 12-2025 | F31: =+YEAR(Tabla2[[#This Row],[Cosecha]]) -> 2025 | G31: 03-2026 | H31: =(YEAR(G31)-YEAR(E31))*12+(MONTH(G31)-MONTH(E31)) -> 3 | I31: Efectivo | J31: 03-2026 | K31: =(YEAR(J31)-YEAR(E31))*12+(MONTH(J31)-MONTH(E31)) -> 3 | L31: KDM116A | M31: TOYOTA AVANZA | N31: UBER | P31: Año Cosecha | Q31: Avg. Meses transcurridos | R31: Max. Meses transcurridos | S31: Min. Meses transcurridos
A32: ALVARADO CERVANTES JONATHAN JACOB | B32: Hombre | C32: 4571AF | D32: BAJA CALIFORNIA | E32: 04-2025 | F32: =+YEAR(Tabla2[[#This Row],[Cosecha]]) -> 2025 | G32: 09-2025 | H32: =(YEAR(G32)-YEAR(E32))*12+(MONTH(G32)-MONTH(E32)) -> 5 | I32: Efectivo | J32: 10-2025 | K32: =(YEAR(J32)-YEAR(E32))*12+(MONTH(J32)-MONTH(E32)) -> 6 | L32: BWX672A | M32: CHEVROLET AVEO | N32: UBER | P32: 2022 | Q32: =+ROUND(AVERAGEIF(Tabla2[Año Cosecha],P32,Tabla2[Meses transcurridos]),0) -> 32 | R32: =_xlfn.MAXIFS(Tabla2[Meses transcurridos],Tabla2[Año Cosecha],P32) -> 36 | S32: =_xlfn.MINIFS(Tabla2[Meses transcurridos],Tabla2[Año Cosecha],P32) -> 26
A33: ALVARADO DE LA ROCHA CARLOS ALBERTO | B33: Hombre | C33: 3962AF | D33: CDMX Y AREA METROPOLITANA | E33: 11-2024 | F33: =+YEAR(Tabla2[[#This Row],[Cosecha]]) -> 2024 | G33: 12-2025 | H33: =(YEAR(G33)-YEAR(E33))*12+(MONTH(G33)-MONTH(E33)) -> 13 | I33: Efectivo | J33: 01-2026 | K33: =(YEAR(J33)-YEAR(E33))*12+(MONTH(J33)-MONTH(E33)) -> 14 | L33: 13G727 | M33: BYD D1 | N33: UBER | P33: 2023 | Q33: =+ROUND(AVERAGEIF(Tabla2[Año Cosecha],P33,Tabla2[Meses transcurridos]),0) -> 24 | R33: =_xlfn.MAXIFS(Tabla2[Meses transcurridos],Tabla2[Año Cosecha],P33) -> 37 | S33: =_xlfn.MINIFS(Tabla2[Meses transcurridos],Tabla2[Año Cosecha],P33) -> 13
A34: ALVARADO DIAZ ADRIAN | B34: Hombre | C34: 4125AF | D34: CDMX Y AREA METROPOLITANA | E34: 12-2024 | F34: =+YEAR(Tabla2[[#This Row],[Cosecha]]) -> 2024 | G34: 07-2025 | H34: =(YEAR(G34)-YEAR(E34))*12+(MONTH(G34)-MONTH(E34)) -> 7 | I34: Efectivo | J34: 08-2025 | K34: =(YEAR(J34)-YEAR(E34))*12+(MONTH(J34)-MONTH(E34)) -> 8 | L34: 19G588 | M34: BYD D1 | N34: UBER | P34: 2024 | Q34: =+ROUND(AVERAGEIF(Tabla2[Año Cosecha],P34,Tabla2[Meses transcurridos]),0) -> 12 | R34: =_xlfn.MAXIFS(Tabla2[Meses transcurridos],Tabla2[Año Cosecha],P34) -> 27 | S34: =_xlfn.MINIFS(Tabla2[Meses transcurridos],Tabla2[Año Cosecha],P34) -> 1
A35: ALVARADO FLORES ERIK | B35: Hombre | C35: 3871AF | D35: CDMX Y AREA METROPOLITANA | E35: 10-2024 | F35: =+YEAR(Tabla2[[#This Row],[Cosecha]]) -> 2024 | G35: 09-2025 | H35: =(YEAR(G35)-YEAR(E35))*12+(MONTH(G35)-MONTH(E35)) -> 11 | I35: Efectivo | J35: 09-2025 | K35: =(YEAR(J35)-YEAR(E35))*12+(MONTH(J35)-MONTH(E35)) -> 11 | L35: E10BPT | M35: TOYOTA AVANZA | N35: UBER | P35: 2025 | Q35: =+ROUND(AVERAGEIF(Tabla2[Año Cosecha],P35,Tabla2[Meses transcurridos]),0) -> 6 | R35: =_xlfn.MAXIFS(Tabla2[Meses transcurridos],Tabla2[Año Cosecha],P35) -> 15 | S35: =_xlfn.MINIFS(Tabla2[Meses transcurridos],Tabla2[Año Cosecha],P35) -> 0
A36: ALVARADO JUAREZ LUIS ADAN | B36: Hombre | C36: 5633AF | D36: CDMX Y AREA METROPOLITANA | E36: 08-2025 | F36: =+YEAR(Tabla2[[#This Row],[Cosecha]]) -> 2025 | G36: 04-2026 | H36: =(YEAR(G36)-YEAR(E36))*12+(MONTH(G36)-MONTH(E36)) -> 8 | I36: Efectivo | J36: 04-2026 | K36: =(YEAR(J36)-YEAR(E36))*12+(MONTH(J36)-MONTH(E36)) -> 8 | L36: 48G289 | M36: BYD MINIDOLPHIN | N36: UBER | P36: 2026 | Q36: =+ROUND(AVERAGEIF(Tabla2[Año Cosecha],P36,Tabla2[Meses transcurridos]),0) -> 2 | R36: =_xlfn.MAXIFS(Tabla2[Meses transcurridos],Tabla2[Año Cosecha],P36) -> 4 | S36: =_xlfn.MINIFS(Tabla2[Meses transcurridos],Tabla2[Año Cosecha],P36) -> 1
A37: ALVARADO MARTINEZ ENRIQUE ALFREDO | B37: Hombre | C37: 6374AF | D37: NUEVO LEON | E37: 11-2025 | F37: =+YEAR(Tabla2[[#This Row],[Cosecha]]) -> 2025 | G37: 03-2026 | H37: =(YEAR(G37)-YEAR(E37))*12+(MONTH(G37)-MONTH(E37)) -> 4 | I37: Efectivo | J37: 03-2026 | K37: =(YEAR(J37)-YEAR(E37))*12+(MONTH(J37)-MONTH(E37)) -> 4 | L37: RYJ862C | M37: TOYOTA AVANZA | N37: UBER | P37: Promedio | Q37: =+AVERAGE(Q32:Q36) -> 15.2 | R37: =+AVERAGE(R32:R36) -> 23.8 | S37: =+AVERAGE(S32:S36) -> 8.2
A38: ALVARADO ORDUÑA LUIS | B38: Hombre | C38: 4252AF | D38: CDMX Y AREA METROPOLITANA | E38: 01-2025 | F38: =+YEAR(Tabla2[[#This Row],[Cosecha]]) -> 2025 | G38: 03-2026 | H38: =(YEAR(G38)-YEAR(E38))*12+(MONTH(G38)-MONTH(E38)) -> 14 | I38: Efectivo | J38: 03-2026 | K38: =(YEAR(J38)-YEAR(E38))*12+(MONTH(J38)-MONTH(E38)) -> 14 | L38: A08BNM | M38: CHEVROLET AVEO | N38: UBER
A39: ALVAREZ BARROSO LUIS ARTURO | B39: Hombre | C39: 5379AF | D39: CDMX Y AREA METROPOLITANA | E39: 07-2025 | F39: =+YEAR(Tabla2[[#This Row],[Cosecha]]) -> 2025 | G39: 01-2026 | H39: =(YEAR(G39)-YEAR(E39))*12+(MONTH(G39)-MONTH(E39)) -> 6 | I39: Efectivo | J39: 01-2026 | K39: =(YEAR(J39)-YEAR(E39))*12+(MONTH(J39)-MONTH(E39)) -> 6 | L39: 48G159 | M39: BYD MINIDOLPHIN | N39: UBER | P39: Año Cosecha | Q39: Cantidad
A40: ALVAREZ BONES OSVALDO | B40: Hombre | C40: 4899AF | D40: CDMX Y AREA METROPOLITANA | E40: 05-2025 | F40: =+YEAR(Tabla2[[#This Row],[Cosecha]]) -> 2025 | G40: 11-2025 | H40: =(YEAR(G40)-YEAR(E40))*12+(MONTH(G40)-MONTH(E40)) -> 6 | I40: Efectivo | J40: 11-2025 | K40: =(YEAR(J40)-YEAR(E40))*12+(MONTH(J40)-MONTH(E40)) -> 6 | L40: 13G735 | M40: BYD D1 | N40: UBER | P40: 2022 | Q40: =COUNTIF(F:F,P40) -> 12
...

Sheet Originaciones
C4: Units | D4: Source
B6: Month Start | E6: 44927 | F6: 44958 | G6: 44986 | H6: 45017 | I6: 45047 | J6: 45078 | K6: 45108 | L6: 45139 | M6: 45170 | N6: 45200 | O6: 45231 | P6: 45261 | Q6: 45292 | R6: =+Q7+1 -> 45323 | S6: =+R7+1 -> 45352 | T6: =+S7+1 -> 45383 | U6: =+T7+1 -> 45413 | V6: =+U7+1 -> 45444 | W6: =+V7+1 -> 45474 | X6: =+W7+1 -> 45505 | Y6: =+X7+1 -> 45536 | ... AB6: =+AA7+1 -> 45627 | AC6: 45658 | AD6: =+AC7+1 -> 45689 | AE6: =+AD7+1 -> 45717 | AF6: =+AE7+1 -> 45748 | AG6: =+AF7+1 -> 45778 | AH6: =+AG7+1 -> 45809 | AI6: =+AH7+1 -> 45839 | AJ6: =+AI7+1 -> 45870 | AK6: =+AJ7+1 -> 45901 | ... AZ6: =+AY7+1 -> 46357
B7: Month End | E7: 44957 | F7: 44985 | G7: 45016 | H7: 45046 | I7: 45077 | J7: 45107 | K7: 45138 | L7: 45169 | M7: 45199 | N7: 45230 | O7: 45260 | P7: 45291 | Q7: =+EOMONTH(Q6,0) -> 45322 | R7: =+EOMONTH(Q7,1) -> 45351 | S7: =+EOMONTH(R7,1) -> 45382 | T7: =+EOMONTH(S7,1) -> 45412 | U7: =+EOMONTH(T7,1) -> 45443 | V7: =+EOMONTH(U7,1) -> 45473 | W7: =+EOMONTH(V7,1) -> 45504 | X7: =+EOMONTH(W7,1) -> 45535 | Y7: =+EOMONTH(X7,1) -> 45565 | ... AB7: =+EOMONTH(AA7,1) -> 45657 | AC7: =+EOMONTH(AC6,0) -> 45688 | AD7: =+EOMONTH(AD6,0) -> 45716 | AE7: =+EOMONTH(AE6,0) -> 45747 | AF7: =+EOMONTH(AF6,0) -> 45777 | AG7: =+EOMONTH(AG6,0) -> 45808 | AH7: =+EOMONTH(AH6,0) -> 45838 | AI7: =+EOMONTH(AI6,0) -> 45869 | AJ7: =+EOMONTH(AJ6,0) -> 45900 | ... AZ7: =+EOMONTH(AZ6,0) -> 46387
B8: Year | E8: 2023 | F8: 2023 | G8: 2023 | H8: 2023 | I8: 2023 | J8: 2023 | K8: 2023 | L8: 2023 | M8: 2023 | N8: 2023 | O8: 2023 | P8: 2023 | Q8: =+YEAR(Q7) -> 2024 | R8: =+YEAR(R7) -> 2024 | S8: =+YEAR(S7) -> 2024 | T8: =+YEAR(T7) -> 2024 | U8: =+YEAR(U7) -> 2024 | V8: =+YEAR(V7) -> 2024 | W8: =+YEAR(W7) -> 2024 | X8: =+YEAR(X7) -> 2024 | ... AZ8: =+YEAR(AZ7) -> 2026
B9: Month | E9: =+UPPER(TEXT(E7, "mmm")) -> ENE | F9: =+UPPER(TEXT(F7, "mmm")) -> FEB | G9: =+UPPER(TEXT(G7, "mmm")) -> MAR | H9: =+UPPER(TEXT(H7, "mmm")) -> ABR | I9: =+UPPER(TEXT(I7, "mmm")) -> MAY | J9: =+UPPER(TEXT(J7, "mmm")) -> JUN | K9: =+UPPER(TEXT(K7, "mmm")) -> JUL | L9: =+UPPER(TEXT(L7, "mmm")) -> AGO | ... AZ9: =+UPPER(TEXT(AZ7, "mmm")) -> DIC
B10: Quarter | E10: Q1 | F10: Q1 | G10: Q1 | H10: Q2 | I10: Q2 | J10: Q2 | K10: Q3 | L10: Q3 | M10: Q3 | N10: Q4 | O10: Q4 | P10: Q4 | Q10: Q1 | R10: Q1 | S10: Q1 | T10: Q2 | U10: Q2 | V10: Q2 | W10: Q3 | X10: Q3 | Y10: Q3 | Z10: Q4 | AA10: Q4 | AB10: Q4 | AC10: Q1 | AD10: Q1 | AE10: Q1 | AF10: Q2 | AG10: Q2 | AH10: Q2 | AI10: Q3 | AJ10: Q3 | AK10: Q3 | AL10: Q4 | AM10: Q4 | AN10: Q4 | AO10: Q1 | AP10: Q1 | AQ10: Q1 | AR10: Q2 | AS10: #NAME? | AT10: #NAME? | AU10: #NAME? | AV10: #NAME? | AW10: #NAME? | AX10: #NAME? | AY10: #NAME? | AZ10: #NAME?
B11: Fridays Per Month | E11: =+(E7-E6+1)-NETWORKDAYS.INTL(E6,E7,16) -> 4 | F11: =+(F7-F6+1)-NETWORKDAYS.INTL(F6,F7,16) -> 4 | G11: =+(G7-G6+1)-NETWORKDAYS.INTL(G6,G7,16) -> 5 | H11: =+(H7-H6+1)-NETWORKDAYS.INTL(H6,H7,16) -> 4 | I11: =+(I7-I6+1)-NETWORKDAYS.INTL(I6,I7,16) -> 4 | J11: =+(J7-J6+1)-NETWORKDAYS.INTL(J6,J7,16) -> 5 | K11: =+(K7-K6+1)-NETWORKDAYS.INTL(K6,K7,16) -> 4 | L11: =+(L7-L6+1)-NETWORKDAYS.INTL(L6,L7,16) -> 4 | ... AZ11: =+(AZ7-AZ6+1)-NETWORKDAYS.INTL(AZ6,AZ7,16) -> 4
B12: Actual | E12: Actual | F12: Actual | G12: Actual | H12: Actual | I12: Actual | J12: Actual | K12: Actual | L12: Actual | M12: Actual | N12: Actual | O12: Actual | P12: Actual | Q12: Actual | R12: Actual | S12: Actual | T12: Actual | U12: Actual | V12: Actual | W12: Actual | X12: Actual | Y12: Actual | Z12: Actual | AA12: Actual | AB12: Actual | AC12: Actual | AD12: Actual | AE12: Actual | AF12: Actual | AG12: Actual | AH12: Actual | AI12: Actual | AJ12: Actual | AK12: Actual | AL12: Actual | AM12: Actual | AN12: Actual | AO12: Actual | AP12: Actual | AQ12: Actual | AR12: Actual | AS12: #NAME? | AT12: #NAME? | AU12: #NAME? | AV12: #NAME? | AW12: #NAME? | AX12: #NAME? | AY12: #NAME? | AZ12: #NAME?
B14: LTO Main KPIs
B16: Origination (New Vehicles)
B18: Origination | C18: [#] | E18: =+SUM(E19:E21) -> 36 | F18: =+SUM(F19:F21) -> 31 | G18: =+SUM(G19:G21) -> 30 | H18: =+SUM(H19:H21) -> 27 | I18: =+SUM(I19:I21) -> 28 | J18: =+SUM(J19:J21) -> 44 | K18: =+SUM(K19:K21) -> 43 | L18: =+SUM(L19:L21) -> 50 | ... AZ18: =+SUM(AZ19:AZ21) -> 0
B19: ICE | C19: [#] | D19: LTO Report | E19: 36 | F19: 31 | G19: 24 | H19: 17 | I19: 21 | J19: 37 | K19: 38 | L19: 36 | M19: 38 | N19: 33 | O19: 46 | P19: 30 | Q19: 46 | R19: 44 | S19: 37 | T19: 49 | U19: 62 | V19: 47 | W19: 60 | X19: 57 | Y19: 72 | Z19: 75 | AA19: 38 | AB19: 13 | AC19: 29 | AD19: 44 | AE19: 29 | AF19: 50 | AG19: 66 | AH19: 98 | AI19: 70 | AJ19: 57 | AK19: =50+15 -> 65 | AL19: 113 | AM19: 98 | AN19: 105 | AO19: 75 | AP19: 74 | AQ19: 59 | AR19: 69
B20: HEV | C20: [#] | D20: LTO Report | E20: 0 | F20: 0 | G20: 6 | H20: 7 | I20: 3 | J20: 5 | K20: 3 | L20: 8 | M20: 17 | N20: 14 | O20: 8 | P20: 5 | Q20: 2 | R20: 10 | S20: 4 | T20: 5 | U20: 4 | V20: 3 | W20: 8 | X20: 10 | Y20: 3 | Z20: 1 | AA20: 0 | AB20: 0 | AC20: 0 | AD20: 0 | AE20: 0 | AF20: 0 | AG20: 0 | AH20: 0 | AI20: 0 | AJ20: 0 | AK20: 0 | AL20: 0 | AM20: 0 | AN20: 0 | AO20: 0 | AP20: 0 | AQ20: 0 | AR20: 0
B21: EV | C21: [#] | D21: LTO Report | E21: 0 | F21: 0 | G21: 0 | H21: 3 | I21: 4 | J21: 2 | K21: 2 | L21: 6 | M21: 0 | N21: 4 | O21: 4 | P21: 1 | Q21: 15 | R21: 14 | S21: 19 | T21: 19 | U21: 28 | V21: 53 | W21: 51 | X21: 47 | Y21: 37 | Z21: 44 | AA21: 57 | AB21: 92 | AC21: 68 | AD21: 55 | AE21: 107 | AF21: 111 | AG21: 91 | AH21: 97 | AI21: 129 | AJ21: =93+16 -> 109 | AK21: =122-16+9 -> 115 | AL21: 93 | AM21: 113 | AN21: 110 | AO21: 100 | AP21: 127 | AQ21: 118 | AR21: 149
B23: Origination | C23: [%] | E23: =+SUM(E24:E26) -> 1 | F23: =+SUM(F24:F26) -> 1 | G23: =+SUM(G24:G26) -> 1 | H23: =+SUM(H24:H26) -> 1 | I23: =+SUM(I24:I26) -> 1 | J23: =+SUM(J24:J26) -> 1 | K23: =+SUM(K24:K26) -> 1 | L23: =+SUM(L24:L26) -> 1 | ... AZ23: =+SUM(AZ24:AZ26) -> 0
B24: ICE | C24: [%] | E24: =+IFERROR(E19/E$18,"0") -> 1 | F24: =+IFERROR(F19/F$18,"0") -> 1 | G24: =+IFERROR(G19/G$18,"0") -> 0.8 | H24: =+IFERROR(H19/H$18,"0") -> 0.62962963 | I24: =+IFERROR(I19/I$18,"0") -> 0.75 | J24: =+IFERROR(J19/J$18,"0") -> 0.84090909 | K24: =+IFERROR(K19/K$18,"0") -> 0.88372093 | L24: =+IFERROR(L19/L$18,"0") -> 0.72 | ... AZ24: =+IFERROR(AZ19/AZ$18,"0") -> 0
B25: HEV | C25: [%] | E25: =+IFERROR(E20/E$18,"0") -> 0 | F25: =+IFERROR(F20/F$18,"0") -> 0 | G25: =+IFERROR(G20/G$18,"0") -> 0.2 | H25: =+IFERROR(H20/H$18,"0") -> 0.25925926 | I25: =+IFERROR(I20/I$18,"0") -> 0.10714286 | J25: =+IFERROR(J20/J$18,"0") -> 0.11363636 | K25: =+IFERROR(K20/K$18,"0") -> 0.069767442 | L25: =+IFERROR(L20/L$18,"0") -> 0.16 | ... AZ25: =+IFERROR(AZ20/AZ$18,"0") -> 0
B26: EV | C26: [%] | E26: =+IFERROR(E21/E$18,"0") -> 0 | F26: =+IFERROR(F21/F$18,"0") -> 0 | G26: =+IFERROR(G21/G$18,"0") -> 0 | H26: =+IFERROR(H21/H$18,"0") -> 0.11111111 | I26: =+IFERROR(I21/I$18,"0") -> 0.14285714 | J26: =+IFERROR(J21/J$18,"0") -> 0.045454545 | K26: =+IFERROR(K21/K$18,"0") -> 0.046511628 | L26: =+IFERROR(L21/L$18,"0") -> 0.12 | ... AZ26: =+IFERROR(AZ21/AZ$18,"0") -> 0
B28: Origination by Platform | C28: [#] | E28: =+SUM(E29:E30) -> 36 | F28: =+SUM(F29:F30) -> 31 | G28: =+SUM(G29:G30) -> 30 | H28: =+SUM(H29:H30) -> 27 | I28: =+SUM(I29:I30) -> 28 | J28: =+SUM(J29:J30) -> 44 | K28: =+SUM(K29:K30) -> 43 | L28: =+SUM(L29:L30) -> 50 | ... AB28: =+SUM(AB29:AB30) -> 105 | AC28: =+SUM(AC29:AC31) -> 97 | AD28: =+SUM(AD29:AD31) -> 99 | AE28: =+SUM(AE29:AE31) -> 136 | AF28: =+SUM(AF29:AF31) -> 161 | AG28: =+SUM(AG29:AG31) -> 157 | AH28: =+SUM(AH29:AH31) -> 195 | AI28: =+SUM(AI29:AI31) -> 199 | AJ28: =+SUM(AJ29:AJ31) -> 166 | ... AZ28: =+SUM(AZ29:AZ31) -> 0
B29: Uber | C29: [#] | D29: LTO Report | E29: =E32 -> 36 | F29: =F32 -> 31 | G29: =G32 -> 30 | H29: =H32 -> 27 | I29: =I32 -> 28 | J29: =J32 -> 44 | K29: =K32 -> 43 | L29: =L32 -> 50 | ... AB29: =AB32 -> 89 | AC29: 74 | AD29: 75 | AE29: 121 | AF29: 124 | AG29: 97 | AH29: 153 | AI29: 147 | AJ29: =117+16 -> 133 | AK29: 134 | AL29: 154 | AM29: 161 | AN29: 166 | AO29: 121 | AP29: 157 | AQ29: 124 | AR29: 165
B30: DiDi | C30: [#] | D30: LTO Report | E30: =E37 -> 0 | F30: =F37 -> 0 | G30: =G37 -> 0 | H30: =H37 -> 0 | I30: =I37 -> 0 | J30: =J37 -> 0 | K30: =K37 -> 0 | L30: =L37 -> 0 | ... AB30: =AB37 -> 16 | AC30: 23 | AD30: 24 | AE30: 15 | AF30: 37 | AG30: 60 | AH30: 42 | AI30: 52 | AJ30: 33 | AK30: 46 | AL30: 52 | AM30: 50 | AN30: 49 | AO30: 54 | AP30: 44 | AQ30: 53 | AR30: 53
B32: Origination in Uber by vehicle type | C32: [#] | E32: =+SUM(E33:E35) -> 36 | F32: =+SUM(F33:F35) -> 31 | G32: =+SUM(G33:G35) -> 30 | H32: =+SUM(H33:H35) -> 27 | I32: =+SUM(I33:I35) -> 28 | J32: =+SUM(J33:J35) -> 44 | K32: =+SUM(K33:K35) -> 43 | L32: =+SUM(L33:L35) -> 50 | ... AZ32: =+SUM(AZ33:AZ35) -> 0
B33: ICE | C33: [#] | D33: LTO Report | E33: 36 | F33: 31 | G33: 24 | H33: 17 | I33: 21 | J33: 37 | K33: 38 | L33: 36 | M33: 38 | N33: 33 | O33: 46 | P33: 30 | Q33: 46 | R33: 44 | S33: 36 | T33: 48 | U33: 61 | V33: 47 | W33: 60 | X33: 57 | Y33: 72 | Z33: 73 | AA33: 37 | AB33: 13 | AC33: 29 | AD33: 43 | AE33: 28 | AF33: 48 | AG33: 38 | AH33: 68 | AI33: 49 | AJ33: 41 | AK33: 44 | AL33: 78 | AM33: 63 | AN33: 78 | AO33: 49 | AP33: 56 | AQ33: 41 | AR33: 58
B34: HEV | C34: [#] | D34: LTO Report | E34: 0 | F34: 0 | G34: 6 | H34: 7 | I34: 3 | J34: 5 | K34: 3 | L34: 8 | M34: 17 | N34: 14 | O34: 8 | P34: 5 | Q34: 2 | R34: 10 | S34: 4 | T34: 5 | U34: 4 | V34: 3 | W34: 8 | X34: 10 | Y34: 3 | Z34: 1 | AA34: 0 | AB34: 0 | AC34: 0 | AD34: 0 | AE34: 0 | AF34: 0 | AG34: 0 | AH34: 0 | AI34: 0 | AJ34: 0 | AK34: 0 | AL34: 0 | AM34: 0 | AN34: 0 | AO34: 0 | AP34: 0 | AQ34: 0 | AR34: 0
B35: EV | C35: [#] | D35: LTO Report | E35: 0 | F35: 0 | G35: 0 | H35: 3 | I35: 4 | J35: 2 | K35: 2 | L35: 6 | M35: 0 | N35: 4 | O35: 4 | P35: 1 | Q35: 15 | R35: 14 | S35: 19 | T35: 19 | U35: 28 | V35: 53 | W35: 49 | X35: 31 | Y35: 18 | Z35: 26 | AA35: 41 | AB35: 76 | AC35: 45 | AD35: 32 | AE35: 93 | AF35: 76 | AG35: 59 | AH35: 85 | AI35: 98 | AJ35: =76+16 -> 92 | AK35: 90 | AL35: 76 | AM35: 98 | AN35: 88 | AO35: 72 | AP35: 101 | AQ35: 83 | AR35: 107
B37: Origination in DiDi by vehicle type | C37: [#] | E37: =+SUM(E38:E40) -> 0 | F37: =+SUM(F38:F40) -> 0 | G37: =+SUM(G38:G40) -> 0 | H37: =+SUM(H38:H40) -> 0 | I37: =+SUM(I38:I40) -> 0 | J37: =+SUM(J38:J40) -> 0 | K37: =+SUM(K38:K40) -> 0 | L37: =+SUM(L38:L40) -> 0 | ... AZ37: =+SUM(AZ38:AZ40) -> 0
B38: ICE | C38: [#] | D38: LTO Report | Q38: 0 | R38: 0 | S38: 0 | T38: 0 | U38: 0 | V38: 0 | W38: 0 | X38: 0 | Y38: 0 | Z38: 0 | AA38: 0 | AB38: 0 | AC38: 0 | AD38: 1 | AE38: 1 | AF38: 2 | AG38: 28 | AH38: 30 | AI38: 21 | AJ38: 16 | AK38: 21 | AL38: 35 | AM38: 35 | AN38: 27 | AO38: 26 | AP38: 18 | AQ38: 18 | AR38: 11
B39: HEV | C39: [#] | D39: LTO Report | Q39: 0 | R39: 0 | S39: 0 | T39: 0 | U39: 0 | V39: 0 | W39: 0 | X39: 0 | Y39: 0 | Z39: 0 | AA39: 0 | AB39: 0 | AC39: 0 | AD39: 0 | AE39: 0 | AF39: 0 | AG39: 0 | AH39: 0 | AI39: 0 | AJ39: 0 | AK39: 0 | AL39: 0 | AM39: 0 | AN39: 0 | AO39: 0 | AP39: 0 | AQ39: 0 | AR39: 0
B40: EV | C40: [#] | D40: LTO Report | Q40: 0 | R40: 0 | S40: 0 | T40: 0 | U40: 0 | V40: 0 | W40: 0 | X40: 0 | Y40: 0 | Z40: 0 | AA40: 0 | AB40: 16 | AC40: 23 | AD40: 23 | AE40: 14 | AF40: 35 | AG40: 32 | AH40: 12 | AI40: 31 | AJ40: 17 | AK40: 25 | AL40: 17 | AM40: 15 | AN40: 22 | AO40: 28 | AP40: 26 | AQ40: 35 | AR40: 42
B42: Origination (Used Vehicles)
B44: Used Vehicle Origination | C44: [#] | Q44: =SUM(Q45:Q47) -> 0 | R44: =SUM(R45:R47) -> 0 | S44: =SUM(S45:S47) -> 0 | T44: =SUM(T45:T47) -> 0 | U44: =SUM(U45:U47) -> 0 | V44: =SUM(V45:V47) -> 0 | W44: =SUM(W45:W47) -> 0 | X44: =SUM(X45:X47) -> 0 | ... AZ44: =SUM(AZ45:AZ47) -> 0
B45: ICE | C45: [#] | D45: LTO Report | Q45: 0 | R45: 0 | S45: 0 | T45: 0 | U45: 0 | V45: 0 | W45: 0 | X45: 0 | Y45: 0 | Z45: 0 | AA45: 10 | AB45: 9 | AC45: 5 | AD45: 10 | AE45: 15 | AF45: 7 | AG45: 1 | AH45: 7 | AI45: 9 | AJ45: 9 | AK45: 2 | AL45: 5 | AM45: 4 | AN45: 3 | AO45: 6 | AP45: 2 | AQ45: 11 | AR45: 4
B46: HEV | C46: [#] | D46: LTO Report | Q46: 0 | R46: 0 | S46: 0 | T46: 0 | U46: 0 | V46: 0 | W46: 0 | X46: 0 | Y46: 0 | Z46: 0 | AA46: 0 | AB46: 2 | AC46: 3 | AD46: 0 | AE46: 1 | AF46: 2 | AG46: 1 | AH46: 1 | AI46: 1 | AJ46: 0 | AK46: 0 | AL46: 0 | AM46: 0 | AN46: 0 | AO46: 0 | AP46: 1 | AQ46: 1 | AR46: 0
B47: EV | C47: [#] | D47: LTO Report | Q47: 0 | R47: 0 | S47: 0 | T47: 0 | U47: 0 | V47: 0 | W47: 0 | X47: 0 | Y47: 0 | Z47: 0 | AA47: 2 | AB47: 0 | AC47: 0 | AD47: 4 | AE47: 3 | AF47: 9 | AG47: 18 | AH47: 15 | AI47: 23 | AJ47: 22 | AK47: 20 | AL47: 21 | AM47: 15 | AN47: 13 | AO47: 22 | AP47: 42 | AQ47: 40 | AR47: 30
B49: Used Vehicle as % of Origination | C49: [#] | Q49: =+Q44/Q14 -> #DIV/0! | R49: =+R44/R14 -> #DIV/0! | S49: =+S44/S14 -> #DIV/0! | T49: =+T44/T14 -> #DIV/0! | U49: =+U44/U14 -> #DIV/0! | V49: =+V44/V14 -> #DIV/0! | W49: =+W44/W14 -> #DIV/0! | X49: =+X44/X14 -> #DIV/0! | ... AB49: =+AB44/AB14 -> #DIV/0! | AC49: =+AC44/AC18 -> 0.082474227 | AD49: =+AD44/AD18 -> 0.14141414 | AE49: =+AE44/AE18 -> 0.13970588 | AF49: =+AF44/AF18 -> 0.11180124 | AG49: =+AG44/AG18 -> 0.12738854 | AH49: =+AH44/AH18 -> 0.11794872 | AI49: =+AI44/AI18 -> 0.16582915 | AJ49: =+AJ44/AJ18 -> 0.18674699 | AK49: =+SUM(AK50:AK52) -> 1 | AL49: =+SUM(AL50:AL52) -> 1 | AM49: =+SUM(AM50:AM52) -> 1 | AN49: =+SUM(AN50:AN52) -> 1 | AO49: =+SUM(AO50:AO52) -> 1 | AP49: =+SUM(AP50:AP52) -> 1 | AQ49: =+SUM(AQ50:AQ52) -> 1 | AR49: =+SUM(AR50:AR52) -> 1 | ... AZ49: =+SUM(AZ50:AZ52) -> 0
B50: ICE | C50: [#] | D50: LTO Report | Q50: =IFERROR(Q45/Q$18,0) -> 0 | R50: =IFERROR(R45/R$18,0) -> 0 | S50: =IFERROR(S45/S$18,0) -> 0 | T50: =IFERROR(T45/T$18,0) -> 0 | U50: =IFERROR(U45/U$18,0) -> 0 | V50: =IFERROR(V45/V$18,0) -> 0 | W50: =IFERROR(W45/W$18,0) -> 0 | X50: =IFERROR(X45/X$18,0) -> 0 | ... AB50: =IFERROR(AB45/AB$18,0) -> 0.085714286 | AC50: =IFERROR(AC45/AC$44,0) -> 0.625 | AD50: =IFERROR(AD45/AD$44,0) -> 0.71428571 | AE50: =IFERROR(AE45/AE$44,0) -> 0.78947368 | AF50: =IFERROR(AF45/AF$44,0) -> 0.38888889 | AG50: =IFERROR(AG45/AG$44,0) -> 0.05 | AH50: =IFERROR(AH45/AH$44,0) -> 0.30434783 | AI50: =IFERROR(AI45/AI$44,0) -> 0.27272727 | AJ50: =IFERROR(AJ45/AJ$44,0) -> 0.29032258 | ... AR50: =IFERROR(AR45/AR$44,0) -> 0.11764706 | AS50: =IFERROR(AS45/AS$18,0) -> 0 | AT50: =IFERROR(AT45/AT$18,0) -> 0 | AU50: =IFERROR(AU45/AU$18,0) -> 0 | AV50: =IFERROR(AV45/AV$18,0) -> 0 | AW50: =IFERROR(AW45/AW$18,0) -> 0 | AX50: =IFERROR(AX45/AX$18,0) -> 0 | AY50: =IFERROR(AY45/AY$18,0) -> 0 | AZ50: =IFERROR(AZ45/AZ$18,0) -> 0
B51: HEV | C51: [#] | D51: LTO Report | Q51: =IFERROR(Q46/Q$18,0) -> 0 | R51: =IFERROR(R46/R$18,0) -> 0 | S51: =IFERROR(S46/S$18,0) -> 0 | T51: =IFERROR(T46/T$18,0) -> 0 | U51: =IFERROR(U46/U$18,0) -> 0 | V51: =IFERROR(V46/V$18,0) -> 0 | W51: =IFERROR(W46/W$18,0) -> 0 | X51: =IFERROR(X46/X$18,0) -> 0 | ... AB51: =IFERROR(AB46/AB$18,0) -> 0.019047619 | AC51: =IFERROR(AC46/AC$44,0) -> 0.375 | AD51: =IFERROR(AD46/AD$44,0) -> 0 | AE51: =IFERROR(AE46/AE$44,0) -> 0.052631579 | AF51: =IFERROR(AF46/AF$44,0) -> 0.11111111 | AG51: =IFERROR(AG46/AG$44,0) -> 0.05 | AH51: =IFERROR(AH46/AH$44,0) -> 0.043478261 | AI51: =IFERROR(AI46/AI$44,0) -> 0.03030303 | AJ51: =IFERROR(AJ46/AJ$44,0) -> 0 | ... AR51: =IFERROR(AR46/AR$44,0) -> 0 | AS51: =IFERROR(AS46/AS$18,0) -> 0 | AT51: =IFERROR(AT46/AT$18,0) -> 0 | AU51: =IFERROR(AU46/AU$18,0) -> 0 | AV51: =IFERROR(AV46/AV$18,0) -> 0 | AW51: =IFERROR(AW46/AW$18,0) -> 0 | AX51: =IFERROR(AX46/AX$18,0) -> 0 | AY51: =IFERROR(AY46/AY$18,0) -> 0 | AZ51: =IFERROR(AZ46/AZ$18,0) -> 0
B52: EV | C52: [#] | D52: LTO Report | Q52: =IFERROR(Q47/Q$18,0) -> 0 | R52: =IFERROR(R47/R$18,0) -> 0 | S52: =IFERROR(S47/S$18,0) -> 0 | T52: =IFERROR(T47/T$18,0) -> 0 | U52: =IFERROR(U47/U$18,0) -> 0 | V52: =IFERROR(V47/V$18,0) -> 0 | W52: =IFERROR(W47/W$18,0) -> 0 | X52: =IFERROR(X47/X$18,0) -> 0 | ... AB52: =IFERROR(AB47/AB$18,0) -> 0 | AC52: =IFERROR(AC47/AC$44,0) -> 0 | AD52: =IFERROR(AD47/AD$44,0) -> 0.28571429 | AE52: =IFERROR(AE47/AE$44,0) -> 0.15789474 | AF52: =IFERROR(AF47/AF$44,0) -> 0.5 | AG52: =IFERROR(AG47/AG$44,0) -> 0.9 | AH52: =IFERROR(AH47/AH$44,0) -> 0.65217391 | AI52: =IFERROR(AI47/AI$44,0) -> 0.6969697 | AJ52: =IFERROR(AJ47/AJ$44,0) -> 0.70967742 | ... AR52: =IFERROR(AR47/AR$44,0) -> 0.88235294 | AS52: =IFERROR(AS47/AS$18,0) -> 0 | AT52: =IFERROR(AT47/AT$18,0) -> 0 | AU52: =IFERROR(AU47/AU$18,0) -> 0 | AV52: =IFERROR(AV47/AV$18,0) -> 0 | AW52: =IFERROR(AW47/AW$18,0) -> 0 | AX52: =IFERROR(AX47/AX$18,0) -> 0 | AY52: =IFERROR(AY47/AY$18,0) -> 0 | AZ52: =IFERROR(AZ47/AZ$18,0) -> 0
B54: Used Vehicle Origination in Uber by vehicle type | C54: [#] | Q54: =+SUM(Q55:Q57) -> 0 | R54: =+SUM(R55:R57) -> 0 | S54: =+SUM(S55:S57) -> 0 | T54: =+SUM(T55:T57) -> 0 | U54: =+SUM(U55:U57) -> 0 | V54: =+SUM(V55:V57) -> 0 | W54: =+SUM(W55:W57) -> 0 | X54: =+SUM(X55:X57) -> 0 | ... AZ54: =+SUM(AZ55:AZ57) -> 0
B55: ICE | C55: [#] | D55: LTO Report | Q55: 0 | R55: 0 | S55: 0 | T55: 0 | U55: 0 | V55: 0 | W55: 0 | X55: 0 | Y55: 0 | Z55: 0 | AA55: 0 | AB55: 9 | AC55: 5 | AD55: 10 | AE55: 14 | AF55: 7 | AG55: 1 | AH55: 4 | AI55: 7 | AJ55: 7 | AK55: 2 | AL55: 3 | AM55: 0 | AN55: 2 | AO55: 1 | AP55: 2 | AQ55: 9 | AR55: 3
...

Sheet Cohort Detail
A1: Cohort Detail — Repossession Analytics (2024–2026)
A3: ⚡ All values are live formulas pulling from Export, recuperación efectiva and Originaciones sheets
A4: Cohort | B4: Originations | C4: Sent to Recovery | D4: Repossessed | E4: Pending | F4: % Repossessed
A5: 01-2024 | B5: =IFERROR(INDEX(Originaciones!$E$18:$AZ$18,MATCH(DATE(VALUE(RIGHT(A5,4)),VALUE(LEFT(A5,2)),1),Originaciones!$E$6:$AZ$6,0)),"-") -> 63 | C5: =COUNTIF(Export!$E:$E,A5) -> 8 | D5: =COUNTIF('recuperación efectiva'!$E:$E,A5) -> 3 | E5: =C5-D5 -> 5 | F5: =IFERROR(D5/C5,0) -> 0.375
A6: 02-2024 | B6: =IFERROR(INDEX(Originaciones!$E$18:$AZ$18,MATCH(DATE(VALUE(RIGHT(A6,4)),VALUE(LEFT(A6,2)),1),Originaciones!$E$6:$AZ$6,0)),"-") -> 68 | C6: =COUNTIF(Export!$E:$E,A6) -> 18 | D6: =COUNTIF('recuperación efectiva'!$E:$E,A6) -> 11 | E6: =C6-D6 -> 7 | F6: =IFERROR(D6/C6,0) -> 0.61111111
A7: 03-2024 | B7: =IFERROR(INDEX(Originaciones!$E$18:$AZ$18,MATCH(DATE(VALUE(RIGHT(A7,4)),VALUE(LEFT(A7,2)),1),Originaciones!$E$6:$AZ$6,0)),"-") -> 60 | C7: =COUNTIF(Export!$E:$E,A7) -> 16 | D7: =COUNTIF('recuperación efectiva'!$E:$E,A7) -> 15 | E7: =C7-D7 -> 1 | F7: =IFERROR(D7/C7,0) -> 0.9375
A8: 04-2024 | B8: =IFERROR(INDEX(Originaciones!$E$18:$AZ$18,MATCH(DATE(VALUE(RIGHT(A8,4)),VALUE(LEFT(A8,2)),1),Originaciones!$E$6:$AZ$6,0)),"-") -> 73 | C8: =COUNTIF(Export!$E:$E,A8) -> 18 | D8: =COUNTIF('recuperación efectiva'!$E:$E,A8) -> 11 | E8: =C8-D8 -> 7 | F8: =IFERROR(D8/C8,0) -> 0.61111111
A9: 05-2024 | B9: =IFERROR(INDEX(Originaciones!$E$18:$AZ$18,MATCH(DATE(VALUE(RIGHT(A9,4)),VALUE(LEFT(A9,2)),1),Originaciones!$E$6:$AZ$6,0)),"-") -> 94 | C9: =COUNTIF(Export!$E:$E,A9) -> 21 | D9: =COUNTIF('recuperación efectiva'!$E:$E,A9) -> 15 | E9: =C9-D9 -> 6 | F9: =IFERROR(D9/C9,0) -> 0.71428571
A10: 06-2024 | B10: =IFERROR(INDEX(Originaciones!$E$18:$AZ$18,MATCH(DATE(VALUE(RIGHT(A10,4)),VALUE(LEFT(A10,2)),1),Originaciones!$E$6:$AZ$6,0)),"-") -> 103 | C10: =COUNTIF(Export!$E:$E,A10) -> 20 | D10: =COUNTIF('recuperación efectiva'!$E:$E,A10) -> 18 | E10: =C10-D10 -> 2 | F10: =IFERROR(D10/C10,0) -> 0.9
A11: 07-2024 | B11: =IFERROR(INDEX(Originaciones!$E$18:$AZ$18,MATCH(DATE(VALUE(RIGHT(A11,4)),VALUE(LEFT(A11,2)),1),Originaciones!$E$6:$AZ$6,0)),"-") -> 119 | C11: =COUNTIF(Export!$E:$E,A11) -> 39 | D11: =COUNTIF('recuperación efectiva'!$E:$E,A11) -> 28 | E11: =C11-D11 -> 11 | F11: =IFERROR(D11/C11,0) -> 0.71794872
A12: 08-2024 | B12: =IFERROR(INDEX(Originaciones!$E$18:$AZ$18,MATCH(DATE(VALUE(RIGHT(A12,4)),VALUE(LEFT(A12,2)),1),Originaciones!$E$6:$AZ$6,0)),"-") -> 114 | C12: =COUNTIF(Export!$E:$E,A12) -> 41 | D12: =COUNTIF('recuperación efectiva'!$E:$E,A12) -> 34 | E12: =C12-D12 -> 7 | F12: =IFERROR(D12/C12,0) -> 0.82926829
A13: 09-2024 | B13: =IFERROR(INDEX(Originaciones!$E$18:$AZ$18,MATCH(DATE(VALUE(RIGHT(A13,4)),VALUE(LEFT(A13,2)),1),Originaciones!$E$6:$AZ$6,0)),"-") -> 112 | C13: =COUNTIF(Export!$E:$E,A13) -> 28 | D13: =COUNTIF('recuperación efectiva'!$E:$E,A13) -> 27 | E13: =C13-D13 -> 1 | F13: =IFERROR(D13/C13,0) -> 0.96428571
A14: 10-2024 | B14: =IFERROR(INDEX(Originaciones!$E$18:$AZ$18,MATCH(DATE(VALUE(RIGHT(A14,4)),VALUE(LEFT(A14,2)),1),Originaciones!$E$6:$AZ$6,0)),"-") -> 120 | C14: =COUNTIF(Export!$E:$E,A14) -> 43 | D14: =COUNTIF('recuperación efectiva'!$E:$E,A14) -> 36 | E14: =C14-D14 -> 7 | F14: =IFERROR(D14/C14,0) -> 0.8372093
A15: 11-2024 | B15: =IFERROR(INDEX(Originaciones!$E$18:$AZ$18,MATCH(DATE(VALUE(RIGHT(A15,4)),VALUE(LEFT(A15,2)),1),Originaciones!$E$6:$AZ$6,0)),"-") -> 95 | C15: =COUNTIF(Export!$E:$E,A15) -> 42 | D15: =COUNTIF('recuperación efectiva'!$E:$E,A15) -> 34 | E15: =C15-D15 -> 8 | F15: =IFERROR(D15/C15,0) -> 0.80952381
A16: 12-2024 | B16: =IFERROR(INDEX(Originaciones!$E$18:$AZ$18,MATCH(DATE(VALUE(RIGHT(A16,4)),VALUE(LEFT(A16,2)),1),Originaciones!$E$6:$AZ$6,0)),"-") -> 105 | C16: =COUNTIF(Export!$E:$E,A16) -> 60 | D16: =COUNTIF('recuperación efectiva'!$E:$E,A16) -> 55 | E16: =C16-D16 -> 5 | F16: =IFERROR(D16/C16,0) -> 0.91666667
... A31: 03-2026 | B31: =IFERROR(INDEX(Originaciones!$E$18:$AZ$18,MATCH(DATE(VALUE(RIGHT(A31,4)),VALUE(LEFT(A31,2)),1),Originaciones!$E$6:$AZ$6,0)),"-") -> 177 | C31: =COUNTIF(Export!$E:$E,A31) -> 2 | D31: =COUNTIF('recuperación efectiva'!$E:$E,A31) -> 2 | E31: =C31-D31 -> 0 | F31: =IFERROR(D31/C31,0) -> 1
A32: TOTAL | B32: =SUM(B5:B31) -> 3701 | C32: =SUM(C5:C31) -> 1200 | D32: =SUM(D5:D31) -> 918 | E32: =SUM(E5:E31) -> 282 | F32: =IFERROR(D32/C32,0) -> 0.765
A34: Formulas: Originations ← Originaciones!row18 (INDEX/MATCH on date) · Sent ← COUNTIF(Export!E) · Repossessed ← COUNTIF(recuperación efectiva!E) · Pending = Sent−Repossessed

Sheet Heatmap
A1: Repossession Heatmap — Cohort × Elapsed Month (Cumulative %)
A3: ⚡ Formulas: n=COUNTIF(Export!E) · % cum = COUNTIFS(recup.ef.!E=cohort, recup.ef.!K<=M) / n · Pyramidal: cells beyond max possible month are blank
A4: Cohort | B4: n sent | C4: maxM | D4: M+0 | E4: M+1 | F4: M+2 | G4: M+3 | H4: M+4 | I4: M+5 | J4: M+6 | K4: M+7 | L4: M+8 | M4: M+9 | N4: M+10 | O4: M+11 | P4: M+12 | Q4: M+13 | R4: M+14 | S4: M+15 | T4: M+16 | U4: M+17 | V4: M+18 | W4: M+19 | X4: M+20 | Y4: M+21 | Z4: M+22 | AA4: M+23 | AB4: M+24 | AC4: M+25 | AD4: M+26 | AE4: M+27 | AF4: M+28 | AG4: M+29 | AH4: M+30 | AI4: M+31 | AJ4: M+32 | AK4: M+33 | AL4: M+34 | AM4: M+35 | AN4: M+36
A5: 01-2024 | B5: =COUNTIF(Export!$E:$E,A5) -> 8 | C5: =MIN(MAX(0,(2026-VALUE(RIGHT(A5,4)))*12+(5-VALUE(LEFT(A5,2)))),36) -> 28 | D5: =IF((COLUMN()-4)>$C5,"",IFERROR(COUNTIFS('recuperación efectiva'!$E:$E,$A5,'recuperación efectiva'!$K:$K,"<="&(COLUMN()-4))/$B5,0)) -> 0 | E5: =IF((COLUMN()-4)>$C5,"",IFERROR(COUNTIFS('recuperación efectiva'!$E:$E,$A5,'recuperación efectiva'!$K:$K,"<="&(COLUMN()-4))/$B5,0)) -> 0 | F5: =IF((COLUMN()-4)>$C5,"",IFERROR(COUNTIFS('recuperación efectiva'!$E:$E,$A5,'recuperación efectiva'!$K:$K,"<="&(COLUMN()-4))/$B5,0)) -> 0 | G5: =IF((COLUMN()-4)>$C5,"",IFERROR(COUNTIFS('recuperación efectiva'!$E:$E,$A5,'recuperación efectiva'!$K:$K,"<="&(COLUMN()-4))/$B5,0)) -> 0 | H5: =IF((COLUMN()-4)>$C5,"",IFERROR(COUNTIFS('recuperación efectiva'!$E:$E,$A5,'recuperación efectiva'!$K:$K,"<="&(COLUMN()-4))/$B5,0)) -> 0 | I5: =IF((COLUMN()-4)>$C5,"",IFERROR(COUNTIFS('recuperación efectiva'!$E:$E,$A5,'recuperación efectiva'!$K:$K,"<="&(COLUMN()-4))/$B5,0)) -> 0 | J5: =IF((COLUMN()-4)>$C5,"",IFERROR(COUNTIFS('recuperación efectiva'!$E:$E,$A5,'recuperación efectiva'!$K:$K,"<="&(COLUMN()-4))/$B5,0)) -> 0 | K5: =IF((COLUMN()-4)>$C5,"",IFERROR(COUNTIFS('recuperación efectiva'!$E:$E,$A5,'recuperación efectiva'!$K:$K,"<="&(COLUMN()-4))/$B5,0)) -> 0 | ... AN5: =IF((COLUMN()-4)>$C5,"",IFERROR(COUNTIFS('recuperación efectiva'!$E:$E,$A5,'recuperación efectiva'!$K:$K,"<="&(COLUMN()-4))/$B5,0))
A6: 02-2024 | B6: =COUNTIF(Export!$E:$E,A6) -> 18 | C6: =MIN(MAX(0,(2026-VALUE(RIGHT(A6,4)))*12+(5-VALUE(LEFT(A6,2)))),36) -> 27 | D6: =IF((COLUMN()-4)>$C6,"",IFERROR(COUNTIFS('recuperación efectiva'!$E:$E,$A6,'recuperación efectiva'!$K:$K,"<="&(COLUMN()-4))/$B6,0)) -> 0 | E6: =IF((COLUMN()-4)>$C6,"",IFERROR(COUNTIFS('recuperación efectiva'!$E:$E,$A6,'recuperación efectiva'!$K:$K,"<="&(COLUMN()-4))/$B6,0)) -> 0 | F6: =IF((COLUMN()-4)>$C6,"",IFERROR(COUNTIFS('recuperación efectiva'!$E:$E,$A6,'recuperación efectiva'!$K:$K,"<="&(COLUMN()-4))/$B6,0)) -> 0 | G6: =IF((COLUMN()-4)>$C6,"",IFERROR(COUNTIFS('recuperación efectiva'!$E:$E,$A6,'recuperación efectiva'!$K:$K,"<="&(COLUMN()-4))/$B6,0)) -> 0 | H6: =IF((COLUMN()-4)>$C6,"",IFERROR(COUNTIFS('recuperación efectiva'!$E:$E,$A6,'recuperación efectiva'!$K:$K,"<="&(COLUMN()-4))/$B6,0)) -> 0 | I6: =IF((COLUMN()-4)>$C6,"",IFERROR(COUNTIFS('recuperación efectiva'!$E:$E,$A6,'recuperación efectiva'!$K:$K,"<="&(COLUMN()-4))/$B6,0)) -> 0 | J6: =IF((COLUMN()-4)>$C6,"",IFERROR(COUNTIFS('recuperación efectiva'!$E:$E,$A6,'recuperación efectiva'!$K:$K,"<="&(COLUMN()-4))/$B6,0)) -> 0 | K6: =IF((COLUMN()-4)>$C6,"",IFERROR(COUNTIFS('recuperación efectiva'!$E:$E,$A6,'recuperación efectiva'!$K:$K,"<="&(COLUMN()-4))/$B6,0)) -> 0 | ... AN6: =IF((COLUMN()-4)>$C6,"",IFERROR(COUNTIFS('recuperación efectiva'!$E:$E,$A6,'recuperación efectiva'!$K:$K,"<="&(COLUMN()-4))/$B6,0))
A7: 03-2024 | B7: =COUNTIF(Export!$E:$E,A7) -> 16 | C7: =MIN(MAX(0,(2026-VALUE(RIGHT(A7,4)))*12+(5-VALUE(LEFT(A7,2)))),36) -> 26 | D7: =IF((COLUMN()-4)>$C7,"",IFERROR(COUNTIFS('recuperación efectiva'!$E:$E,$A7,'recuperación efectiva'!$K:$K,"<="&(COLUMN()-4))/$B7,0)) -> 0 | E7: =IF((COLUMN()-4)>$C7,"",IFERROR(COUNTIFS('recuperación efectiva'!$E:$E,$A7,'recuperación efectiva'!$K:$K,"<="&(COLUMN()-4))/$B7,0)) -> 0 | F7: =IF((COLUMN()-4)>$C7,"",IFERROR(COUNTIFS('recuperación efectiva'!$E:$E,$A7,'recuperación efectiva'!$K:$K,"<="&(COLUMN()-4))/$B7,0)) -> 0 | G7: =IF((COLUMN()-4)>$C7,"",IFERROR(COUNTIFS('recuperación efectiva'!$E:$E,$A7,'recuperación efectiva'!$K:$K,"<="&(COLUMN()-4))/$B7,0)) -> 0 | H7: =IF((COLUMN()-4)>$C7,"",IFERROR(COUNTIFS('recuperación efectiva'!$E:$E,$A7,'recuperación efectiva'!$K:$K,"<="&(COLUMN()-4))/$B7,0)) -> 0 | I7: =IF((COLUMN()-4)>$C7,"",IFERROR(COUNTIFS('recuperación efectiva'!$E:$E,$A7,'recuperación efectiva'!$K:$K,"<="&(COLUMN()-4))/$B7,0)) -> 0 | J7: =IF((COLUMN()-4)>$C7,"",IFERROR(COUNTIFS('recuperación efectiva'!$E:$E,$A7,'recuperación efectiva'!$K:$K,"<="&(COLUMN()-4))/$B7,0)) -> 0 | K7: =IF((COLUMN()-4)>$C7,"",IFERROR(COUNTIFS('recuperación efectiva'!$E:$E,$A7,'recuperación efectiva'!$K:$K,"<="&(COLUMN()-4))/$B7,0)) -> 0 | ... AN7: =IF((COLUMN()-4)>$C7,"",IFERROR(COUNTIFS('recuperación efectiva'!$E:$E,$A7,'recuperación efectiva'!$K:$K,"<="&(COLUMN()-4))/$B7,0))
A8: 04-2024 | B8: =COUNTIF(Export!$E:$E,A8) -> 18 | C8: =MIN(MAX(0,(2026-VALUE(RIGHT(A8,4)))*12+(5-VALUE(LEFT(A8,2)))),36) -> 25 | D8: =IF((COLUMN()-4)>$C8,"",IFERROR(COUNTIFS('recuperación efectiva'!$E:$E,$A8,'recuperación efectiva'!$K:$K,"<="&(COLUMN()-4))/$B8,0)) -> 0 | E8: =IF((COLUMN()-4)>$C8,"",IFERROR(COUNTIFS('recuperación efectiva'!$E:$E,$A8,'recuperación efectiva'!$K:$K,"<="&(COLUMN()-4))/$B8,0)) -> 0 | F8: =IF((COLUMN()-4)>$C8,"",IFERROR(COUNTIFS('recuperación efectiva'!$E:$E,$A8,'recuperación efectiva'!$K:$K,"<="&(COLUMN()-4))/$B8,0)) -> 0 | G8: =IF((COLUMN()-4)>$C8,"",IFERROR(COUNTIFS('recuperación efectiva'!$E:$E,$A8,'recuperación efectiva'!$K:$K,"<="&(COLUMN()-4))/$B8,0)) -> 0 | H8: =IF((COLUMN()-4)>$C8,"",IFERROR(COUNTIFS('recuperación efectiva'!$E:$E,$A8,'recuperación efectiva'!$K:$K,"<="&(COLUMN()-4))/$B8,0)) -> 0 | I8: =IF((COLUMN()-4)>$C8,"",IFERROR(COUNTIFS('recuperación efectiva'!$E:$E,$A8,'recuperación efectiva'!$K:$K,"<="&(COLUMN()-4))/$B8,0)) -> 0 | J8: =IF((COLUMN()-4)>$C8,"",IFERROR(COUNTIFS('recuperación efectiva'!$E:$E,$A8,'recuperación efectiva'!$K:$K,"<="&(COLUMN()-4))/$B8,0)) -> 0 | K8: =IF((COLUMN()-4)>$C8,"",IFERROR(COUNTIFS('recuperación efectiva'!$E:$E,$A8,'recuperación efectiva'!$K:$K,"<="&(COLUMN()-4))/$B8,0)) -> 0 | ... AN8: =IF((COLUMN()-4)>$C8,"",IFERROR(COUNTIFS('recuperación efectiva'!$E:$E,$A8,'recuperación efectiva'!$K:$K,"<="&(COLUMN()-4))/$B8,0))
