Workbook

Sheet Export
A1: ① PEGA AQUÍ EL EXPORT DE POWER BI (desde fila 3, sin encabezados) — Columna M se calcula sola
A2: Cliente | B2: Sexo | C2: Contrato | D2: Estado | E2: Cosecha (MM-YYYY) | F2: Mes Envío Recuperación | G2: Meses Transcurridos | H2: Estatus Recuperación | I2: Mes Recuperación | J2: Plate | K2: Modelo | L2: Plataforma | M2: ⚙ Meses_Efectivos (auto-calculado)
A3: . RODRIGUEZ VICENTE | B3: Hombre | C3: 2519AF | D3: BAJA CALIFORNIA | E3: 04-2023 | F3: 04-2026 | G3: 36 | H3: Efectivo | I3: 04-2026 | J3: BGH042A | K3: ATTITUDE | L3: UBER | M3: =IF(H3="Efectivo",IFERROR((VALUE(RIGHT(I3,4))-VALUE(RIGHT(E3,4)))*12+(VALUE(LEFT(I3,2))-VALUE(LEFT(E3,2))),""),"") -> 36
A4: . RODRIGUEZ VICENTE | B4: Hombre | C4: 6812AF | D4: BAJA CALIFORNIA | E4: 01-2026 | F4: 04-2026 | G4: 2 | H4: Efectivo | I4: 04-2026 | J4: CBY512A | K4: CHEVROLET AVEO | L4: DIDI | M4: =IF(H4="Efectivo",IFERROR((VALUE(RIGHT(I4,4))-VALUE(RIGHT(E4,4)))*12+(VALUE(LEFT(I4,2))-VALUE(LEFT(E4,2))),""),"") -> 3
A5: ACEVES OSUNA FRANCISCO XAVIER | B5: Hombre | C5: 4990AF | D5: BAJA CALIFORNIA | E5: 06-2025 | F5: 03-2026 | G5: 9 | H5: Efectivo | I5: 03-2026 | J5: BYG580A | K5: CHEVROLET AVEO | L5: UBER | M5: =IF(H5="Efectivo",IFERROR((VALUE(RIGHT(I5,4))-VALUE(RIGHT(E5,4)))*12+(VALUE(LEFT(I5,2))-VALUE(LEFT(E5,2))),""),"") -> 9
A6: ACOSTA CALDERON FERNANDO | B6: Hombre | C6: 3908AF | D6: CDMX Y AREA METROPOLITANA | E6: 10-2024 | F6: 10-2025 | G6: 11 | H6: Efectivo | I6: 11-2025 | J6: C34BPX | K6: TOYOTA AVANZA | L6: UBER | M6: =IF(H6="Efectivo",IFERROR((VALUE(RIGHT(I6,4))-VALUE(RIGHT(E6,4)))*12+(VALUE(LEFT(I6,2))-VALUE(LEFT(E6,2))),""),"") -> 13
A7: ACOSTA MARTINEZ MIGUEL ANGEL | B7: Hombre | C7: 5944AF | D7: CDMX Y AREA METROPOLITANA | E7: 10-2025 | F7: 04-2026 | G7: 6 | H7: Pendiente | J7: 51G505 | K7: GAC AION S | L7: UBER | M7: =IF(H7="Efectivo",IFERROR((VALUE(RIGHT(I7,4))-VALUE(RIGHT(E7,4)))*12+(VALUE(LEFT(I7,2))-VALUE(LEFT(E7,2))),""),"")
A8: ADAME SALINAS MICHEL ALBERTO | B8: Hombre | C8: 4523AF | D8: CDMX Y AREA METROPOLITANA | E8: 03-2025 | F8: 11-2025 | G8: 7 | H8: Efectivo | I8: 11-2025 | J8: 39G976 | K8: GAC AION S | L8: UBER | M8: =IF(H8="Efectivo",IFERROR((VALUE(RIGHT(I8,4))-VALUE(RIGHT(E8,4)))*12+(VALUE(LEFT(I8,2))-VALUE(LEFT(E8,2))),""),"") -> 8
A9: ADAME TRUJILLO CHRISTIAN ARIEL | B9: Hombre | C9: 4399AF | D9: CDMX Y AREA METROPOLITANA | E9: 02-2025 | F9: 01-2026 | G9: 11 | H9: Efectivo | I9: 02-2026 | J9: 31G452 | K9: GAC AION S | L9: UBER | M9: =IF(H9="Efectivo",IFERROR((VALUE(RIGHT(I9,4))-VALUE(RIGHT(E9,4)))*12+(VALUE(LEFT(I9,2))-VALUE(LEFT(E9,2))),""),"") -> 12
A10: AGAMA MEJIA ARTEMIO | B10: Hombre | C10: 5022AF | D10: CDMX Y AREA METROPOLITANA | E10: 06-2025 | F10: 03-2026 | G10: 9 | H10: Efectivo | I10: 03-2026 | J10: D96BRR | K10: CHEVROLET AVEO | L10: UBER | M10: =IF(H10="Efectivo",IFERROR((VALUE(RIGHT(I10,4))-VALUE(RIGHT(E10,4)))*12+(VALUE(LEFT(I10,2))-VALUE(LEFT(E10,2))),""),"") -> 9
A11: AGUILAR GONZALEZ MARCO ANTONIO | B11: Hombre | C11: 5011AF | D11: CDMX Y AREA METROPOLITANA | E11: 06-2025 | F11: 03-2026 | G11: 10 | H11: Efectivo | I11: 04-2026 | J11: A84BMP | K11: CHEVROLET AVEO | L11: UBER | M11: =IF(H11="Efectivo",IFERROR((VALUE(RIGHT(I11,4))-VALUE(RIGHT(E11,4)))*12+(VALUE(LEFT(I11,2))-VALUE(LEFT(E11,2))),""),"") -> 10
A12: AGUILAR GONZALEZ MIGUEL ANGEL | B12: Hombre | C12: 3889AF | D12: BAJA CALIFORNIA | E12: 10-2024 | F12: 06-2025 | G12: 8 | H12: Efectivo | I12: 07-2025 | J12: BSG377A | K12: CHEVROLET AVEO | L12: UBER | M12: =IF(H12="Efectivo",IFERROR((VALUE(RIGHT(I12,4))-VALUE(RIGHT(E12,4)))*12+(VALUE(LEFT(I12,2))-VALUE(LEFT(E12,2))),""),"") -> 9
A13: AGUILAR LOPEZ ALFONSO | B13: Hombre | C13: 4270AF | D13: CDMX Y AREA METROPOLITANA | E13: 01-2025 | F13: 02-2026 | G13: 12 | H13: Pendiente | J13: 31G972 | K13: GAC AION S | L13: UBER | M13: =IF(H13="Efectivo",IFERROR((VALUE(RIGHT(I13,4))-VALUE(RIGHT(E13,4)))*12+(VALUE(LEFT(I13,2))-VALUE(LEFT(E13,2))),""),"")
A14: AGUILAR REZA DIEGO ABRAHAM | B14: Hombre | C14: 6245AF | D14: CDMX Y AREA METROPOLITANA | E14: 11-2025 | F14: 04-2026 | G14: 5 | H14: Efectivo | I14: 05-2026 | J14: 62G480 | K14: BYD E5 | L14: UBER | M14: =IF(H14="Efectivo",IFERROR((VALUE(RIGHT(I14,4))-VALUE(RIGHT(E14,4)))*12+(VALUE(LEFT(I14,2))-VALUE(LEFT(E14,2))),""),"") -> 6
A15: AGUILAR TREJO ADAN | B15: Hombre | C15: 5909AF | D15: BAJA CALIFORNIA | E15: 10-2025 | F15: 04-2026 | G15: 6 | H15: Efectivo | I15: 04-2026 | J15: CAJ035A | K15: CHEVROLET AVEO | L15: DIDI | M15: =IF(H15="Efectivo",IFERROR((VALUE(RIGHT(I15,4))-VALUE(RIGHT(E15,4)))*12+(VALUE(LEFT(I15,2))-VALUE(LEFT(E15,2))),""),"") -> 6
A16: AGUILAR VERA OSCAR MAURICIO | B16: Hombre | C16: 4247AF | D16: JALISCO | E16: 01-2025 | F16: 11-2025 | G16: 9 | H16: Efectivo | I16: 03-2026 | J16: HWS688A | K16: CHEVROLET AVEO | L16: UBER | M16: =IF(H16="Efectivo",IFERROR((VALUE(RIGHT(I16,4))-VALUE(RIGHT(E16,4)))*12+(VALUE(LEFT(I16,2))-VALUE(LEFT(E16,2))),""),"") -> 14
A17: AGUIRRE AVALOS CARLOS ALBERTO | B17: Hombre | C17: 4078AF | D17: JALISCO | E17: 12-2024 | F17: 01-2026 | G17: 13 | H17: Efectivo | I17: 01-2026 | J17: HWS689A | K17: CHEVROLET AVEO | L17: UBER | M17: =IF(H17="Efectivo",IFERROR((VALUE(RIGHT(I17,4))-VALUE(RIGHT(E17,4)))*12+(VALUE(LEFT(I17,2))-VALUE(LEFT(E17,2))),""),"") -> 13
A18: AGUIRRE VELAZQUEZ MARIA ANTONIETA | B18: Mujer | C18: 6862AF | D18: CDMX Y AREA METROPOLITANA | E18: 01-2026 | F18: 02-2026 | G18: 1 | H18: Efectivo | I18: 02-2026 | J18: 29G385 | K18: GAC AION S | L18: UBER | M18: =IF(H18="Efectivo",IFERROR((VALUE(RIGHT(I18,4))-VALUE(RIGHT(E18,4)))*12+(VALUE(LEFT(I18,2))-VALUE(LEFT(E18,2))),""),"") -> 1
A19: AGUIRRE ZAZUETA XIUMARA SERAIN | B19: Mujer | C19: 5875AF | D19: NUEVO LEON | E19: 10-2025 | F19: 02-2026 | G19: 4 | H19: Efectivo | I19: 02-2026 | J19: RXW058C | K19: CHEVROLET AVEO | L19: DIDI | M19: =IF(H19="Efectivo",IFERROR((VALUE(RIGHT(I19,4))-VALUE(RIGHT(E19,4)))*12+(VALUE(LEFT(I19,2))-VALUE(LEFT(E19,2))),""),"") -> 4
A20: ALAMILLO CONTRERAS DANIEL | B20: Hombre | C20: 4082AF | D20: NUEVO LEON | E20: 12-2024 | F20: 04-2026 | G20: 16 | H20: Efectivo | I20: 04-2026 | J20: TFP758B | K20: CHEVROLET AVEO | L20: UBER | M20: =IF(H20="Efectivo",IFERROR((VALUE(RIGHT(I20,4))-VALUE(RIGHT(E20,4)))*12+(VALUE(LEFT(I20,2))-VALUE(LEFT(E20,2))),""),"") -> 16
A21: ALANIS ARELLANO LUIS GERARDO | B21: Hombre | C21: 5589AF | D21: NUEVO LEON | E21: 08-2025 | F21: 04-2026 | G21: 7 | H21: Efectivo | I21: 04-2026 | J21: RWL277C | K21: TOYOTA AVANZA | L21: DIDI | M21: =IF(H21="Efectivo",IFERROR((VALUE(RIGHT(I21,4))-VALUE(RIGHT(E21,4)))*12+(VALUE(LEFT(I21,2))-VALUE(LEFT(E21,2))),""),"") -> 8
A22: ALANIS SANTILLAN VICTOR MANUEL | B22: Hombre | C22: 4282AF | D22: CDMX Y AREA METROPOLITANA | E22: 02-2025 | F22: 04-2026 | G22: 14 | H22: Efectivo | I22: 04-2026 | J22: R25BRD | K22: CHEVROLET AVEO | L22: UBER | M22: =IF(H22="Efectivo",IFERROR((VALUE(RIGHT(I22,4))-VALUE(RIGHT(E22,4)))*12+(VALUE(LEFT(I22,2))-VALUE(LEFT(E22,2))),""),"") -> 14
A23: ALARCON MARTINEZ ABRAHAM DANIEL | B23: Hombre | C23: 4771AF | D23: CDMX Y AREA METROPOLITANA | E23: 05-2025 | F23: 01-2026 | G23: 9 | H23: Efectivo | I23: 02-2026 | J23: E68BRR | K23: CHEVROLET AVEO | L23: DIDI | M23: =IF(H23="Efectivo",IFERROR((VALUE(RIGHT(I23,4))-VALUE(RIGHT(E23,4)))*12+(VALUE(LEFT(I23,2))-VALUE(LEFT(E23,2))),""),"") -> 9
A24: ALATORRE MARQUEZ JORGE ALEJANDRO | B24: Hombre | C24: 2944AF | D24: JALISCO | E24: 01-2024 | F24: 03-2026 | G24: 26 | H24: Cancelado | J24: HSJ725A | K24: CHEVROLET AVEO | L24: UBER | M24: =IF(H24="Efectivo",IFERROR((VALUE(RIGHT(I24,4))-VALUE(RIGHT(E24,4)))*12+(VALUE(LEFT(I24,2))-VALUE(LEFT(E24,2))),""),"")
A25: ALBA PARAMO NOE | B25: Hombre | C25: 5625AF | D25: CDMX Y AREA METROPOLITANA | E25: 08-2025 | F25: 12-2025 | G25: 3 | H25: Pendiente | J25: 48G241 | K25: BYD MINIDOLPHIN | L25: DIDI | M25: =IF(H25="Efectivo",IFERROR((VALUE(RIGHT(I25,4))-VALUE(RIGHT(E25,4)))*12+(VALUE(LEFT(I25,2))-VALUE(LEFT(E25,2))),""),"")
A26: ALCALA NOVEROLA MARIO JONATHAN | B26: Hombre | C26: 5784AF | D26: CDMX Y AREA METROPOLITANA | E26: 09-2025 | F26: 02-2026 | G26: 4 | H26: Efectivo | I26: 02-2026 | J26: 10K823 | K26: BYD MINIDOLPHIN | L26: UBER | M26: =IF(H26="Efectivo",IFERROR((VALUE(RIGHT(I26,4))-VALUE(RIGHT(E26,4)))*12+(VALUE(LEFT(I26,2))-VALUE(LEFT(E26,2))),""),"") -> 5
A27: ALCANTAR SILVA ARMANDO | B27: Hombre | C27: 2745AF | D27: BAJA CALIFORNIA | E27: 09-2023 | F27: 06-2025 | G27: 21 | H27: Efectivo | I27: 06-2025 | J27: BJX359A | K27: CHEVROLET AVEO | L27: UBER | M27: =IF(H27="Efectivo",IFERROR((VALUE(RIGHT(I27,4))-VALUE(RIGHT(E27,4)))*12+(VALUE(LEFT(I27,2))-VALUE(LEFT(E27,2))),""),"") -> 21
A28: ALCANTARA SANCHEZ ENRIQUE ABRAHAM | B28: Hombre | C28: 5800AF | D28: CDMX Y AREA METROPOLITANA | E28: 09-2025 | F28: 05-2026 | G28: 7 | H28: Efectivo | I28: 05-2026 | J28: 10K840 | K28: BYD MINIDOLPHIN | L28: UBER | M28: =IF(H28="Efectivo",IFERROR((VALUE(RIGHT(I28,4))-VALUE(RIGHT(E28,4)))*12+(VALUE(LEFT(I28,2))-VALUE(LEFT(E28,2))),""),"") -> 8
A29: ALCANTARA SEGURA JUAN | B29: Hombre | C29: 4370AF | D29: CDMX Y AREA METROPOLITANA | E29: 02-2025 | F29: 06-2025 | G29: 3 | H29: Efectivo | I29: 06-2025 | J29: 19G586 | K29: BYD D1 | L29: UBER | M29: =IF(H29="Efectivo",IFERROR((VALUE(RIGHT(I29,4))-VALUE(RIGHT(E29,4)))*12+(VALUE(LEFT(I29,2))-VALUE(LEFT(E29,2))),""),"") -> 4
A30: ALCIBAR PEÑA DANIEL | B30: Hombre | C30: 4368AF | D30: CDMX Y AREA METROPOLITANA | E30: 02-2025 | F30: 04-2025 | G30: 2 | H30: Efectivo | I30: 05-2025 | J30: 31G788 | K30: GAC AION S | L30: DIDI | M30: =IF(H30="Efectivo",IFERROR((VALUE(RIGHT(I30,4))-VALUE(RIGHT(E30,4)))*12+(VALUE(LEFT(I30,2))-VALUE(LEFT(E30,2))),""),"") -> 3
A31: ALDANA RUIZ ISRAEL | B31: Hombre | C31: 5409AF | D31: CDMX Y AREA METROPOLITANA | E31: 07-2025 | F31: 03-2026 | G31: 8 | H31: Efectivo | I31: 03-2026 | J31: 48G145 | K31: BYD MINIDOLPHIN | L31: DIDI | M31: =IF(H31="Efectivo",IFERROR((VALUE(RIGHT(I31,4))-VALUE(RIGHT(E31,4)))*12+(VALUE(LEFT(I31,2))-VALUE(LEFT(E31,2))),""),"") -> 8
A32: ALDAPE BARCENAS ILSE ABIGAIL | B32: Mujer | C32: 5889AF | D32: NUEVO LEON | E32: 10-2025 | F32: 03-2026 | G32: 6 | H32: Pendiente | J32: RXC615C | K32: TOYOTA AVANZA | L32: UBER | M32: =IF(H32="Efectivo",IFERROR((VALUE(RIGHT(I32,4))-VALUE(RIGHT(E32,4)))*12+(VALUE(LEFT(I32,2))-VALUE(LEFT(E32,2))),""),"")
A33: ALEJANDRE GABRIEL DIEGO | B33: Hombre | C33: 6382AF | D33: NUEVO LEON | E33: 11-2025 | F33: 04-2026 | G33: 4 | H33: Pendiente | J33: RZB056C | K33: CHEVROLET AVEO | L33: DIDI | M33: =IF(H33="Efectivo",IFERROR((VALUE(RIGHT(I33,4))-VALUE(RIGHT(E33,4)))*12+(VALUE(LEFT(I33,2))-VALUE(LEFT(E33,2))),""),"")
A34: ALEMAN CONTRERAS MANUEL ALEJANDRO | B34: Hombre | C34: 6440AF | D34: CDMX Y AREA METROPOLITANA | E34: 12-2025 | F34: 02-2026 | G34: 2 | H34: Pendiente | J34: 51G818 | K34: BYD MINIDOLPHIN | L34: UBER | M34: =IF(H34="Efectivo",IFERROR((VALUE(RIGHT(I34,4))-VALUE(RIGHT(E34,4)))*12+(VALUE(LEFT(I34,2))-VALUE(LEFT(E34,2))),""),"")
A35: ALFARO MARTINEZ LUIS ENRIQUE | B35: Hombre | C35: 3767AF | D35: CDMX Y AREA METROPOLITANA | E35: 09-2024 | F35: 04-2025 | G35: 6 | H35: Efectivo | I35: 04-2025 | J35: 05G231 | K35: BYD D1 | L35: UBER | M35: =IF(H35="Efectivo",IFERROR((VALUE(RIGHT(I35,4))-VALUE(RIGHT(E35,4)))*12+(VALUE(LEFT(I35,2))-VALUE(LEFT(E35,2))),""),"") -> 7
A36: ALMANZA VITE OCTAVIO DAMIAN | B36: Hombre | C36: 4506AF | D36: CDMX Y AREA METROPOLITANA | E36: 03-2025 | F36: 06-2025 | G36: 2 | H36: Efectivo | I36: 06-2025 | J36: Y47BNL | K36: CHEVROLET AVEO | L36: UBER | M36: =IF(H36="Efectivo",IFERROR((VALUE(RIGHT(I36,4))-VALUE(RIGHT(E36,4)))*12+(VALUE(LEFT(I36,2))-VALUE(LEFT(E36,2))),""),"") -> 3
A37: ALONSO ALONSO ROSA CARMEN | B37: Mujer | C37: 4904AF | D37: NUEVO LEON | E37: 05-2025 | F37: 07-2025 | G37: 2 | H37: Efectivo | I37: 08-2025 | J37: RUB750C | K37: TOYOTA AVANZA | L37: DIDI | M37: =IF(H37="Efectivo",IFERROR((VALUE(RIGHT(I37,4))-VALUE(RIGHT(E37,4)))*12+(VALUE(LEFT(I37,2))-VALUE(LEFT(E37,2))),""),"") -> 3
A38: ALONSO DEL ANGEL ALEJANDRO | B38: Hombre | C38: 4167AF | D38: CDMX Y AREA METROPOLITANA | E38: 12-2024 | F38: 03-2026 | G38: 15 | H38: Efectivo | I38: 04-2026 | J38: 19G518 | K38: BYD D1 | L38: UBER | M38: =IF(H38="Efectivo",IFERROR((VALUE(RIGHT(I38,4))-VALUE(RIGHT(E38,4)))*12+(VALUE(LEFT(I38,2))-VALUE(LEFT(E38,2))),""),"") -> 16
A39: ALONSO GUERRA LUIS ALONSO | B39: Hombre | C39: 5550AF | D39: NUEVO LEON | E39: 08-2025 | F39: 02-2026 | G39: 6 | H39: Cancelado | J39: RVX593C | K39: CHEVROLET AVEO | L39: UBER | M39: =IF(H39="Efectivo",IFERROR((VALUE(RIGHT(I39,4))-VALUE(RIGHT(E39,4)))*12+(VALUE(LEFT(I39,2))-VALUE(LEFT(E39,2))),""),"")
A40: ALONSO ROJAS LUIS ENRIQUE | B40: Hombre | C40: 3032AF | D40: CDMX Y AREA METROPOLITANA | E40: 02-2024 | F40: 08-2025 | G40: 18 | H40: Cancelado | J40: T14BNL | K40: CHEVROLET AVEO | L40: UBER | M40: =IF(H40="Efectivo",IFERROR((VALUE(RIGHT(I40,4))-VALUE(RIGHT(E40,4)))*12+(VALUE(LEFT(I40,2))-VALUE(LEFT(E40,2))),""),"")
...

Sheet Originaciones
A1: ② ORIGINACIONES POR COHORTE — agrega filas nuevas al final
A2: Cosecha (MM-YYYY) | B2: N Originaciones | C2: UBER | D2: DIDI
A3: 01-2023 | B3: 36 | C3: 36 | D3: 0
A4: 02-2023 | B4: 31 | C4: 31 | D4: 0
A5: 03-2023 | B5: 30 | C5: 30 | D5: 0
A6: 04-2023 | B6: 27 | C6: 27 | D6: 0
A7: 05-2023 | B7: 28 | C7: 28 | D7: 0
A8: 06-2023 | B8: 44 | C8: 44 | D8: 0
A9: 07-2023 | B9: 43 | C9: 43 | D9: 0
A10: 08-2023 | B10: 50 | C10: 50 | D10: 0
A11: 09-2023 | B11: 55 | C11: 55 | D11: 0
A12: 10-2023 | B12: 51 | C12: 51 | D12: 0
A13: 11-2023 | B13: 58 | C13: 58 | D13: 0
A14: 12-2023 | B14: 36 | C14: 36 | D14: 0
... A42: 04-2026 | B42: 218 | C42: 165 | D42: 53
A43: 05-2026
A44: 06-2026
A45: 07-2026
A46: 08-2026
A47: 09-2026
A48: 10-2026
A49: 11-2026
A50: 12-2026

Sheet Flota Activa
A1: Flota Activa por mes
A2: Cosecha (MM-YYYY) | B2: Flota Activa
A3: 01-2023 | B3: 1339
A4: 02-2023 | B4: 1345
A5: 03-2023 | B5: 1337
A6: 04-2023 | B6: 1331
A7: 05-2023 | B7: 1307
A8: 06-2023 | B8: 1302
A9: 07-2023 | B9: 1313
A10: 08-2023 | B10: 1311
A11: 09-2023 | B11: 1322
A12: 10-2023 | B12: 1321
A13: 11-2023 | B13: 1336
A14: 12-2023 | B14: 1327
... A42: 04-2026 | B42: 3384
A43: 05-2026
A44: 06-2026
A45: 07-2026
A46: 08-2026
A47: 09-2026
A48: 10-2026
A49: 11-2026
A50: 12-2026

Sheet KPIs
A1: RESUMEN GENERAL — se recalcula automáticamente con el Export
A2: KPI | B2: Valor | C2: Descripción
A3: Total enviados a recuperación | B3: =COUNTA(Export!C3:C4000) -> 1289 | C3: Contratos únicos en Export
A4: Total recuperados (Efectivo) | B4: =COUNTIF(Export!H3:H4000,"Efectivo") -> 978 | C4: Estatus = Efectivo
A5: Total pendientes | B5: =COUNTIF(Export!H3:H4000,"Pendiente") -> 206 | C5: Estatus = Pendiente
A6: Total cancelados | B6: =COUNTIF(Export!H3:H4000,"Cancelado") -> 105 | C6: Estatus = Cancelado
A7: Tasa de recuperación (%) | B7: =IFERROR(COUNTIF(Export!H3:H4000,"Efectivo")/COUNTA(Export!C3:C4000)*100,0) -> 75.87277 | C7: Efectivo / Total enviados
A8: UBER — total | B8: =COUNTIF(Export!L3:L4000,"UBER") -> 988 | C8: Plataforma = UBER
A9: DIDI — total | B9: =COUNTIF(Export!L3:L4000,"DIDI") -> 301 | C9: Plataforma = DIDI
A10: Cohortes activas (2024+) | B10: {=SUMPRODUCT((LEN(Export!E3:E4000)>0)*(--ISNUMBER(VALUE(RIGHT(Export!E3:E4000,4))))*(VALUE(RIGHT(Export!E3:E4000,4))>=2024)/1)} -> #VALUE! | C10: Cohortes únicas con datos

Sheet Cohort_Detail
A1: COHORT DETAIL — COUNTIFS sobre Export + Originaciones
A2: Cosecha | B2: N Orig | C2: Sent to Recovery | D2: Repossessed | E2: Pending | F2: % Repossessed | G2: % Sent / Orig | H2: % Reposs / Orig | I2: Cancelados
A3: 01-2024 | B3: =IFERROR(VLOOKUP(A3,Originaciones!$A:$B,2,0),"") -> 63 | C3: =IFERROR(COUNTIF(Export!$E:$E,A3),0) -> 8 | D3: =IFERROR(COUNTIFS(Export!$E:$E,A3,Export!$H:$H,"Efectivo"),0) -> 3 | E3: =IFERROR(COUNTIFS(Export!$E:$E,A3,Export!$H:$H,"Pendiente"),0) -> 1 | F3: =IFERROR(D3/C3,"") -> 0.375 | G3: =IFERROR(C3/B3,"") -> 0.12698413 | H3: =IFERROR(D3/B3,"") -> 0.047619048 | I3: =IFERROR(COUNTIFS(Export!$E:$E,A3,Export!$H:$H,"Cancelado"),0) -> 4
A4: 02-2024 | B4: =IFERROR(VLOOKUP(A4,Originaciones!$A:$B,2,0),"") -> 68 | C4: =IFERROR(COUNTIF(Export!$E:$E,A4),0) -> 18 | D4: =IFERROR(COUNTIFS(Export!$E:$E,A4,Export!$H:$H,"Efectivo"),0) -> 11 | E4: =IFERROR(COUNTIFS(Export!$E:$E,A4,Export!$H:$H,"Pendiente"),0) -> 4 | F4: =IFERROR(D4/C4,"") -> 0.61111111 | G4: =IFERROR(C4/B4,"") -> 0.26470588 | H4: =IFERROR(D4/B4,"") -> 0.16176471 | I4: =IFERROR(COUNTIFS(Export!$E:$E,A4,Export!$H:$H,"Cancelado"),0) -> 3
A5: 03-2024 | B5: =IFERROR(VLOOKUP(A5,Originaciones!$A:$B,2,0),"") -> 60 | C5: =IFERROR(COUNTIF(Export!$E:$E,A5),0) -> 16 | D5: =IFERROR(COUNTIFS(Export!$E:$E,A5,Export!$H:$H,"Efectivo"),0) -> 15 | E5: =IFERROR(COUNTIFS(Export!$E:$E,A5,Export!$H:$H,"Pendiente"),0) -> 0 | F5: =IFERROR(D5/C5,"") -> 0.9375 | G5: =IFERROR(C5/B5,"") -> 0.26666667 | H5: =IFERROR(D5/B5,"") -> 0.25 | I5: =IFERROR(COUNTIFS(Export!$E:$E,A5,Export!$H:$H,"Cancelado"),0) -> 1
A6: 04-2024 | B6: =IFERROR(VLOOKUP(A6,Originaciones!$A:$B,2,0),"") -> 73 | C6: =IFERROR(COUNTIF(Export!$E:$E,A6),0) -> 18 | D6: =IFERROR(COUNTIFS(Export!$E:$E,A6,Export!$H:$H,"Efectivo"),0) -> 11 | E6: =IFERROR(COUNTIFS(Export!$E:$E,A6,Export!$H:$H,"Pendiente"),0) -> 5 | F6: =IFERROR(D6/C6,"") -> 0.61111111 | G6: =IFERROR(C6/B6,"") -> 0.24657534 | H6: =IFERROR(D6/B6,"") -> 0.15068493 | I6: =IFERROR(COUNTIFS(Export!$E:$E,A6,Export!$H:$H,"Cancelado"),0) -> 2
A7: 05-2024 | B7: =IFERROR(VLOOKUP(A7,Originaciones!$A:$B,2,0),"") -> 94 | C7: =IFERROR(COUNTIF(Export!$E:$E,A7),0) -> 21 | D7: =IFERROR(COUNTIFS(Export!$E:$E,A7,Export!$H:$H,"Efectivo"),0) -> 15 | E7: =IFERROR(COUNTIFS(Export!$E:$E,A7,Export!$H:$H,"Pendiente"),0) -> 3 | F7: =IFERROR(D7/C7,"") -> 0.71428571 | G7: =IFERROR(C7/B7,"") -> 0.22340426 | H7: =IFERROR(D7/B7,"") -> 0.15957447 | I7: =IFERROR(COUNTIFS(Export!$E:$E,A7,Export!$H:$H,"Cancelado"),0) -> 3
A8: 06-2024 | B8: =IFERROR(VLOOKUP(A8,Originaciones!$A:$B,2,0),"") -> 103 | C8: =IFERROR(COUNTIF(Export!$E:$E,A8),0) -> 20 | D8: =IFERROR(COUNTIFS(Export!$E:$E,A8,Export!$H:$H,"Efectivo"),0) -> 18 | E8: =IFERROR(COUNTIFS(Export!$E:$E,A8,Export!$H:$H,"Pendiente"),0) -> 1 | F8: =IFERROR(D8/C8,"") -> 0.9 | G8: =IFERROR(C8/B8,"") -> 0.19417476 | H8: =IFERROR(D8/B8,"") -> 0.17475728 | I8: =IFERROR(COUNTIFS(Export!$E:$E,A8,Export!$H:$H,"Cancelado"),0) -> 1
A9: 07-2024 | B9: =IFERROR(VLOOKUP(A9,Originaciones!$A:$B,2,0),"") -> 119 | C9: =IFERROR(COUNTIF(Export!$E:$E,A9),0) -> 39 | D9: =IFERROR(COUNTIFS(Export!$E:$E,A9,Export!$H:$H,"Efectivo"),0) -> 28 | E9: =IFERROR(COUNTIFS(Export!$E:$E,A9,Export!$H:$H,"Pendiente"),0) -> 5 | F9: =IFERROR(D9/C9,"") -> 0.71794872 | G9: =IFERROR(C9/B9,"") -> 0.32773109 | H9: =IFERROR(D9/B9,"") -> 0.23529412 | I9: =IFERROR(COUNTIFS(Export!$E:$E,A9,Export!$H:$H,"Cancelado"),0) -> 6
A10: 08-2024 | B10: =IFERROR(VLOOKUP(A10,Originaciones!$A:$B,2,0),"") -> 114 | C10: =IFERROR(COUNTIF(Export!$E:$E,A10),0) -> 41 | D10: =IFERROR(COUNTIFS(Export!$E:$E,A10,Export!$H:$H,"Efectivo"),0) -> 34 | E10: =IFERROR(COUNTIFS(Export!$E:$E,A10,Export!$H:$H,"Pendiente"),0) -> 2 | F10: =IFERROR(D10/C10,"") -> 0.82926829 | G10: =IFERROR(C10/B10,"") -> 0.35964912 | H10: =IFERROR(D10/B10,"") -> 0.29824561 | I10: =IFERROR(COUNTIFS(Export!$E:$E,A10,Export!$H:$H,"Cancelado"),0) -> 5
A11: 09-2024 | B11: =IFERROR(VLOOKUP(A11,Originaciones!$A:$B,2,0),"") -> 112 | C11: =IFERROR(COUNTIF(Export!$E:$E,A11),0) -> 28 | D11: =IFERROR(COUNTIFS(Export!$E:$E,A11,Export!$H:$H,"Efectivo"),0) -> 27 | E11: =IFERROR(COUNTIFS(Export!$E:$E,A11,Export!$H:$H,"Pendiente"),0) -> 1 | F11: =IFERROR(D11/C11,"") -> 0.96428571 | G11: =IFERROR(C11/B11,"") -> 0.25 | H11: =IFERROR(D11/B11,"") -> 0.24107143 | I11: =IFERROR(COUNTIFS(Export!$E:$E,A11,Export!$H:$H,"Cancelado"),0) -> 0
A12: 10-2024 | B12: =IFERROR(VLOOKUP(A12,Originaciones!$A:$B,2,0),"") -> 120 | C12: =IFERROR(COUNTIF(Export!$E:$E,A12),0) -> 43 | D12: =IFERROR(COUNTIFS(Export!$E:$E,A12,Export!$H:$H,"Efectivo"),0) -> 36 | E12: =IFERROR(COUNTIFS(Export!$E:$E,A12,Export!$H:$H,"Pendiente"),0) -> 2 | F12: =IFERROR(D12/C12,"") -> 0.8372093 | G12: =IFERROR(C12/B12,"") -> 0.35833333 | H12: =IFERROR(D12/B12,"") -> 0.3 | I12: =IFERROR(COUNTIFS(Export!$E:$E,A12,Export!$H:$H,"Cancelado"),0) -> 5
A13: 11-2024 | B13: =IFERROR(VLOOKUP(A13,Originaciones!$A:$B,2,0),"") -> 95 | C13: =IFERROR(COUNTIF(Export!$E:$E,A13),0) -> 42 | D13: =IFERROR(COUNTIFS(Export!$E:$E,A13,Export!$H:$H,"Efectivo"),0) -> 34 | E13: =IFERROR(COUNTIFS(Export!$E:$E,A13,Export!$H:$H,"Pendiente"),0) -> 5 | F13: =IFERROR(D13/C13,"") -> 0.80952381 | G13: =IFERROR(C13/B13,"") -> 0.44210526 | H13: =IFERROR(D13/B13,"") -> 0.35789474 | I13: =IFERROR(COUNTIFS(Export!$E:$E,A13,Export!$H:$H,"Cancelado"),0) -> 3
A14: 12-2024 | B14: =IFERROR(VLOOKUP(A14,Originaciones!$A:$B,2,0),"") -> 105 | C14: =IFERROR(COUNTIF(Export!$E:$E,A14),0) -> 60 | D14: =IFERROR(COUNTIFS(Export!$E:$E,A14,Export!$H:$H,"Efectivo"),0) -> 55 | E14: =IFERROR(COUNTIFS(Export!$E:$E,A14,Export!$H:$H,"Pendiente"),0) -> 3 | F14: =IFERROR(D14/C14,"") -> 0.91666667 | G14: =IFERROR(C14/B14,"") -> 0.57142857 | H14: =IFERROR(D14/B14,"") -> 0.52380952 | I14: =IFERROR(COUNTIFS(Export!$E:$E,A14,Export!$H:$H,"Cancelado"),0) -> 2
... A50: 12-2027 | B50: =IFERROR(VLOOKUP(A50,Originaciones!$A:$B,2,0),"") | C50: =IFERROR(COUNTIF(Export!$E:$E,A50),0) -> 0 | D50: =IFERROR(COUNTIFS(Export!$E:$E,A50,Export!$H:$H,"Efectivo"),0) -> 0 | E50: =IFERROR(COUNTIFS(Export!$E:$E,A50,Export!$H:$H,"Pendiente"),0) -> 0 | F50: =IFERROR(D50/C50,"") | G50: =IFERROR(C50/B50,"") | H50: =IFERROR(D50/B50,"") | I50: =IFERROR(COUNTIFS(Export!$E:$E,A50,Export!$H:$H,"Cancelado"),0) -> 0
A51: TOTAL | B51: =SUM(B3:B50) -> 3919 | C51: =SUM(C3:C50) -> 1200 | D51: =SUM(D3:D50) -> 918 | E51: =SUM(E3:E50) -> 193 | F51: =IFERROR(D51/C51,"") -> 0.765 | G51: =IFERROR(C51/B51,"") -> 0.30620056 | H51: =IFERROR(D51/B51,"") -> 0.23424343 | I51: =SUM(I3:I50) -> 89

Sheet Heatmap
A1: HEATMAP — % acumulado recuperado por cohorte × mes transcurrido (M+0 a M+36)
A2: Cosecha | B2: N Sent | C2: N Orig | D2: M+0 | E2: M+1 | F2: M+2 | G2: M+3 | H2: M+4 | I2: M+5 | J2: M+6 | K2: M+7 | L2: M+8 | M2: M+9 | N2: M+10 | O2: M+11 | P2: M+12 | Q2: M+13 | R2: M+14 | S2: M+15 | T2: M+16 | U2: M+17 | V2: M+18 | W2: M+19 | X2: M+20 | Y2: M+21 | Z2: M+22 | AA2: M+23 | AB2: M+24 | AC2: M+25 | AD2: M+26 | AE2: M+27 | AF2: M+28 | AG2: M+29 | AH2: M+30 | AI2: M+31 | AJ2: M+32 | AK2: M+33 | AL2: M+34 | AM2: M+35 | AN2: M+36
A3: 01-2024 | B3: =IFERROR(COUNTIF(Export!$E:$E,A3),0) -> 8 | C3: =IFERROR(VLOOKUP(A3,Originaciones!$A:$B,2,0),"") -> 63 | D3: =IF(B3=0,"",IFERROR(COUNTIFS(Export!$E:$E,A3,Export!$H:$H,"Efectivo",Export!$M:$M,"<="&0)/B3*100,0)) -> 0 | E3: =IF(B3=0,"",IFERROR(COUNTIFS(Export!$E:$E,A3,Export!$H:$H,"Efectivo",Export!$M:$M,"<="&1)/B3*100,0)) -> 0 | F3: =IF(B3=0,"",IFERROR(COUNTIFS(Export!$E:$E,A3,Export!$H:$H,"Efectivo",Export!$M:$M,"<="&2)/B3*100,0)) -> 0 | G3: =IF(B3=0,"",IFERROR(COUNTIFS(Export!$E:$E,A3,Export!$H:$H,"Efectivo",Export!$M:$M,"<="&3)/B3*100,0)) -> 0 | H3: =IF(B3=0,"",IFERROR(COUNTIFS(Export!$E:$E,A3,Export!$H:$H,"Efectivo",Export!$M:$M,"<="&4)/B3*100,0)) -> 0 | I3: =IF(B3=0,"",IFERROR(COUNTIFS(Export!$E:$E,A3,Export!$H:$H,"Efectivo",Export!$M:$M,"<="&5)/B3*100,0)) -> 0 | J3: =IF(B3=0,"",IFERROR(COUNTIFS(Export!$E:$E,A3,Export!$H:$H,"Efectivo",Export!$M:$M,"<="&6)/B3*100,0)) -> 0 | K3: =IF(B3=0,"",IFERROR(COUNTIFS(Export!$E:$E,A3,Export!$H:$H,"Efectivo",Export!$M:$M,"<="&7)/B3*100,0)) -> 0 | L3: =IF(B3=0,"",IFERROR(COUNTIFS(Export!$E:$E,A3,Export!$H:$H,"Efectivo",Export!$M:$M,"<="&8)/B3*100,0)) -> 0 | M3: =IF(B3=0,"",IFERROR(COUNTIFS(Export!$E:$E,A3,Export!$H:$H,"Efectivo",Export!$M:$M,"<="&9)/B3*100,0)) -> 0 | N3: =IF(B3=0,"",IFERROR(COUNTIFS(Export!$E:$E,A3,Export!$H:$H,"Efectivo",Export!$M:$M,"<="&10)/B3*100,0)) -> 0 | O3: =IF(B3=0,"",IFERROR(COUNTIFS(Export!$E:$E,A3,Export!$H:$H,"Efectivo",Export!$M:$M,"<="&11)/B3*100,0)) -> 0 | P3: =IF(B3=0,"",IFERROR(COUNTIFS(Export!$E:$E,A3,Export!$H:$H,"Efectivo",Export!$M:$M,"<="&12)/B3*100,0)) -> 0 | Q3: =IF(B3=0,"",IFERROR(COUNTIFS(Export!$E:$E,A3,Export!$H:$H,"Efectivo",Export!$M:$M,"<="&13)/B3*100,0)) -> 0 | R3: =IF(B3=0,"",IFERROR(COUNTIFS(Export!$E:$E,A3,Export!$H:$H,"Efectivo",Export!$M:$M,"<="&14)/B3*100,0)) -> 12.5 | S3: =IF(B3=0,"",IFERROR(COUNTIFS(Export!$E:$E,A3,Export!$H:$H,"Efectivo",Export!$M:$M,"<="&15)/B3*100,0)) -> 12.5 | T3: =IF(B3=0,"",IFERROR(COUNTIFS(Export!$E:$E,A3,Export!$H:$H,"Efectivo",Export!$M:$M,"<="&16)/B3*100,0)) -> 12.5 | U3: =IF(B3=0,"",IFERROR(COUNTIFS(Export!$E:$E,A3,Export!$H:$H,"Efectivo",Export!$M:$M,"<="&17)/B3*100,0)) -> 12.5 | V3: =IF(B3=0,"",IFERROR(COUNTIFS(Export!$E:$E,A3,Export!$H:$H,"Efectivo",Export!$M:$M,"<="&18)/B3*100,0)) -> 12.5 | W3: =IF(B3=0,"",IFERROR(COUNTIFS(Export!$E:$E,A3,Export!$H:$H,"Efectivo",Export!$M:$M,"<="&19)/B3*100,0)) -> 12.5 | X3: =IF(B3=0,"",IFERROR(COUNTIFS(Export!$E:$E,A3,Export!$H:$H,"Efectivo",Export!$M:$M,"<="&20)/B3*100,0)) -> 12.5 | Y3: =IF(B3=0,"",IFERROR(COUNTIFS(Export!$E:$E,A3,Export!$H:$H,"Efectivo",Export!$M:$M,"<="&21)/B3*100,0)) -> 12.5 | Z3: =IF(B3=0,"",IFERROR(COUNTIFS(Export!$E:$E,A3,Export!$H:$H,"Efectivo",Export!$M:$M,"<="&22)/B3*100,0)) -> 12.5 | AA3: =IF(B3=0,"",IFERROR(COUNTIFS(Export!$E:$E,A3,Export!$H:$H,"Efectivo",Export!$M:$M,"<="&23)/B3*100,0)) -> 12.5 | AB3: =IF(B3=0,"",IFERROR(COUNTIFS(Export!$E:$E,A3,Export!$H:$H,"Efectivo",Export!$M:$M,"<="&24)/B3*100,0)) -> 12.5 | AC3: =IF(B3=0,"",IFERROR(COUNTIFS(Export!$E:$E,A3,Export!$H:$H,"Efectivo",Export!$M:$M,"<="&25)/B3*100,0)) -> 25 | AD3: =IF(B3=0,"",IFERROR(COUNTIFS(Export!$E:$E,A3,Export!$H:$H,"Efectivo",Export!$M:$M,"<="&26)/B3*100,0)) -> 37.5 | AE3: =IF(B3=0,"",IFERROR(COUNTIFS(Export!$E:$E,A3,Export!$H:$H,"Efectivo",Export!$M:$M,"<="&27)/B3*100,0)) -> 37.5 | AF3: =IF(B3=0,"",IFERROR(COUNTIFS(Export!$E:$E,A3,Export!$H:$H,"Efectivo",Export!$M:$M,"<="&28)/B3*100,0)) -> 37.5 | AG3: =IF(B3=0,"",IFERROR(COUNTIFS(Export!$E:$E,A3,Export!$H:$H,"Efectivo",Export!$M:$M,"<="&29)/B3*100,0)) -> 37.5 | AH3: =IF(B3=0,"",IFERROR(COUNTIFS(Export!$E:$E,A3,Export!$H:$H,"Efectivo",Export!$M:$M,"<="&30)/B3*100,0)) -> 37.5 | AI3: =IF(B3=0,"",IFERROR(COUNTIFS(Export!$E:$E,A3,Export!$H:$H,"Efectivo",Export!$M:$M,"<="&31)/B3*100,0)) -> 37.5 | AJ3: =IF(B3=0,"",IFERROR(COUNTIFS(Export!$E:$E,A3,Export!$H:$H,"Efectivo",Export!$M:$M,"<="&32)/B3*100,0)) -> 37.5 | AK3: =IF(B3=0,"",IFERROR(COUNTIFS(Export!$E:$E,A3,Export!$H:$H,"Efectivo",Export!$M:$M,"<="&33)/B3*100,0)) -> 37.5 | AL3: =IF(B3=0,"",IFERROR(COUNTIFS(Export!$E:$E,A3,Export!$H:$H,"Efectivo",Export!$M:$M,"<="&34)/B3*100,0)) -> 37.5 | AM3: =IF(B3=0,"",IFERROR(COUNTIFS(Export!$E:$E,A3,Export!$H:$H,"Efectivo",Export!$M:$M,"<="&35)/B3*100,0)) -> 37.5 | AN3: =IF(B3=0,"",IFERROR(COUNTIFS(Export!$E:$E,A3,Export!$H:$H,"Efectivo",Export!$M:$M,"<="&36)/B3*100,0)) -> 37.5
A4: 02-2024 | B4: =IFERROR(COUNTIF(Export!$E:$E,A4),0) -> 18 | C4: =IFERROR(VLOOKUP(A4,Originaciones!$A:$B,2,0),"") -> 68 | D4: =IF(B4=0,"",IFERROR(COUNTIFS(Export!$E:$E,A4,Export!$H:$H,"Efectivo",Export!$M:$M,"<="&0)/B4*100,0)) -> 0 | E4: =IF(B4=0,"",IFERROR(COUNTIFS(Export!$E:$E,A4,Export!$H:$H,"Efectivo",Export!$M:$M,"<="&1)/B4*100,0)) -> 0 | F4: =IF(B4=0,"",IFERROR(COUNTIFS(Export!$E:$E,A4,Export!$H:$H,"Efectivo",Export!$M:$M,"<="&2)/B4*100,0)) -> 0 | G4: =IF(B4=0,"",IFERROR(COUNTIFS(Export!$E:$E,A4,Export!$H:$H,"Efectivo",Export!$M:$M,"<="&3)/B4*100,0)) -> 0 | H4: =IF(B4=0,"",IFERROR(COUNTIFS(Export!$E:$E,A4,Export!$H:$H,"Efectivo",Export!$M:$M,"<="&4)/B4*100,0)) -> 0 | I4: =IF(B4=0,"",IFERROR(COUNTIFS(Export!$E:$E,A4,Export!$H:$H,"Efectivo",Export!$M:$M,"<="&5)/B4*100,0)) -> 0 | J4: =IF(B4=0,"",IFERROR(COUNTIFS(Export!$E:$E,A4,Export!$H:$H,"Efectivo",Export!$M:$M,"<="&6)/B4*100,0)) -> 0 | K4: =IF(B4=0,"",IFERROR(COUNTIFS(Export!$E:$E,A4,Export!$H:$H,"Efectivo",Export!$M:$M,"<="&7)/B4*100,0)) -> 0 | L4: =IF(B4=0,"",IFERROR(COUNTIFS(Export!$E:$E,A4,Export!$H:$H,"Efectivo",Export!$M:$M,"<="&8)/B4*100,0)) -> 0 | M4: =IF(B4=0,"",IFERROR(COUNTIFS(Export!$E:$E,A4,Export!$H:$H,"Efectivo",Export!$M:$M,"<="&9)/B4*100,0)) -> 0 | N4: =IF(B4=0,"",IFERROR(COUNTIFS(Export!$E:$E,A4,Export!$H:$H,"Efectivo",Export!$M:$M,"<="&10)/B4*100,0)) -> 0 | O4: =IF(B4=0,"",IFERROR(COUNTIFS(Export!$E:$E,A4,Export!$H:$H,"Efectivo",Export!$M:$M,"<="&11)/B4*100,0)) -> 0 | P4: =IF(B4=0,"",IFERROR(COUNTIFS(Export!$E:$E,A4,Export!$H:$H,"Efectivo",Export!$M:$M,"<="&12)/B4*100,0)) -> 0 | Q4: =IF(B4=0,"",IFERROR(COUNTIFS(Export!$E:$E,A4,Export!$H:$H,"Efectivo",Export!$M:$M,"<="&13)/B4*100,0)) -> 11.111111 | R4: =IF(B4=0,"",IFERROR(COUNTIFS(Export!$E:$E,A4,Export!$H:$H,"Efectivo",Export!$M:$M,"<="&14)/B4*100,0)) -> 11.111111 | S4: =IF(B4=0,"",IFERROR(COUNTIFS(Export!$E:$E,A4,Export!$H:$H,"Efectivo",Export!$M:$M,"<="&15)/B4*100,0)) -> 22.222222 | T4: =IF(B4=0,"",IFERROR(COUNTIFS(Export!$E:$E,A4,Export!$H:$H,"Efectivo",Export!$M:$M,"<="&16)/B4*100,0)) -> 22.222222 | U4: =IF(B4=0,"",IFERROR(COUNTIFS(Export!$E:$E,A4,Export!$H:$H,"Efectivo",Export!$M:$M,"<="&17)/B4*100,0)) -> 22.222222 | V4: =IF(B4=0,"",IFERROR(COUNTIFS(Export!$E:$E,A4,Export!$H:$H,"Efectivo",Export!$M:$M,"<="&18)/B4*100,0)) -> 22.222222 | W4: =IF(B4=0,"",IFERROR(COUNTIFS(Export!$E:$E,A4,Export!$H:$H,"Efectivo",Export!$M:$M,"<="&19)/B4*100,0)) -> 27.777778 | X4: =IF(B4=0,"",IFERROR(COUNTIFS(Export!$E:$E,A4,Export!$H:$H,"Efectivo",Export!$M:$M,"<="&20)/B4*100,0)) -> 38.888889 | Y4: =IF(B4=0,"",IFERROR(COUNTIFS(Export!$E:$E,A4,Export!$H:$H,"Efectivo",Export!$M:$M,"<="&21)/B4*100,0)) -> 38.888889 | Z4: =IF(B4=0,"",IFERROR(COUNTIFS(Export!$E:$E,A4,Export!$H:$H,"Efectivo",Export!$M:$M,"<="&22)/B4*100,0)) -> 38.888889 | AA4: =IF(B4=0,"",IFERROR(COUNTIFS(Export!$E:$E,A4,Export!$H:$H,"Efectivo",Export!$M:$M,"<="&23)/B4*100,0)) -> 44.444444 | AB4: =IF(B4=0,"",IFERROR(COUNTIFS(Export!$E:$E,A4,Export!$H:$H,"Efectivo",Export!$M:$M,"<="&24)/B4*100,0)) -> 55.555556 | AC4: =IF(B4=0,"",IFERROR(COUNTIFS(Export!$E:$E,A4,Export!$H:$H,"Efectivo",Export!$M:$M,"<="&25)/B4*100,0)) -> 55.555556 | AD4: =IF(B4=0,"",IFERROR(COUNTIFS(Export!$E:$E,A4,Export!$H:$H,"Efectivo",Export!$M:$M,"<="&26)/B4*100,0)) -> 55.555556 | AE4: =IF(B4=0,"",IFERROR(COUNTIFS(Export!$E:$E,A4,Export!$H:$H,"Efectivo",Export!$M:$M,"<="&27)/B4*100,0)) -> 61.111111 | AF4: =IF(B4=0,"",IFERROR(COUNTIFS(Export!$E:$E,A4,Export!$H:$H,"Efectivo",Export!$M:$M,"<="&28)/B4*100,0)) -> 61.111111 | AG4: =IF(B4=0,"",IFERROR(COUNTIFS(Export!$E:$E,A4,Export!$H:$H,"Efectivo",Export!$M:$M,"<="&29)/B4*100,0)) -> 61.111111 | AH4: =IF(B4=0,"",IFERROR(COUNTIFS(Export!$E:$E,A4,Export!$H:$H,"Efectivo",Export!$M:$M,"<="&30)/B4*100,0)) -> 61.111111 | AI4: =IF(B4=0,"",IFERROR(COUNTIFS(Export!$E:$E,A4,Export!$H:$H,"Efectivo",Export!$M:$M,"<="&31)/B4*100,0)) -> 61.111111 | AJ4: =IF(B4=0,"",IFERROR(COUNTIFS(Export!$E:$E,A4,Export!$H:$H,"Efectivo",Export!$M:$M,"<="&32)/B4*100,0)) -> 61.111111 | AK4: =IF(B4=0,"",IFERROR(COUNTIFS(Export!$E:$E,A4,Export!$H:$H,"Efectivo",Export!$M:$M,"<="&33)/B4*100,0)) -> 61.111111 | AL4: =IF(B4=0,"",IFERROR(COUNTIFS(Export!$E:$E,A4,Export!$H:$H,"Efectivo",Export!$M:$M,"<="&34)/B4*100,0)) -> 61.111111 | AM4: =IF(B4=0,"",IFERROR(COUNTIFS(Export!$E:$E,A4,Export!$H:$H,"Efectivo",Export!$M:$M,"<="&35)/B4*100,0)) -> 61.111111 | AN4: =IF(B4=0,"",IFERROR(COUNTIFS(Export!$E:$E,A4,Export!$H:$H,"Efectivo",Export!$M:$M,"<="&36)/B4*100,0)) -> 61.111111
A5: 03-2024 | B5: =IFERROR(COUNTIF(Export!$E:$E,A5),0) -> 16 | C5: =IFERROR(VLOOKUP(A5,Originaciones!$A:$B,2,0),"") -> 60 | D5: =IF(B5=0,"",IFERROR(COUNTIFS(Export!$E:$E,A5,Export!$H:$H,"Efectivo",Export!$M:$M,"<="&0)/B5*100,0)) -> 0 | E5: =IF(B5=0,"",IFERROR(COUNTIFS(Export!$E:$E,A5,Export!$H:$H,"Efectivo",Export!$M:$M,"<="&1)/B5*100,0)) -> 0 | F5: =IF(B5=0,"",IFERROR(COUNTIFS(Export!$E:$E,A5,Export!$H:$H,"Efectivo",Export!$M:$M,"<="&2)/B5*100,0)) -> 0 | G5: =IF(B5=0,"",IFERROR(COUNTIFS(Export!$E:$E,A5,Export!$H:$H,"Efectivo",Export!$M:$M,"<="&3)/B5*100,0)) -> 0 | H5: =IF(B5=0,"",IFERROR(COUNTIFS(Export!$E:$E,A5,Export!$H:$H,"Efectivo",Export!$M:$M,"<="&4)/B5*100,0)) -> 0 | I5: =IF(B5=0,"",IFERROR(COUNTIFS(Export!$E:$E,A5,Export!$H:$H,"Efectivo",Export!$M:$M,"<="&5)/B5*100,0)) -> 0 | J5: =IF(B5=0,"",IFERROR(COUNTIFS(Export!$E:$E,A5,Export!$H:$H,"Efectivo",Export!$M:$M,"<="&6)/B5*100,0)) -> 0 | K5: =IF(B5=0,"",IFERROR(COUNTIFS(Export!$E:$E,A5,Export!$H:$H,"Efectivo",Export!$M:$M,"<="&7)/B5*100,0)) -> 0 | L5: =IF(B5=0,"",IFERROR(COUNTIFS(Export!$E:$E,A5,Export!$H:$H,"Efectivo",Export!$M:$M,"<="&8)/B5*100,0)) -> 0 | M5: =IF(B5=0,"",IFERROR(COUNTIFS(Export!$E:$E,A5,Export!$H:$H,"Efectivo",Export!$M:$M,"<="&9)/B5*100,0)) -> 0 | N5: =IF(B5=0,"",IFERROR(COUNTIFS(Export!$E:$E,A5,Export!$H:$H,"Efectivo",Export!$M:$M,"<="&10)/B5*100,0)) -> 12.5 | O5: =IF(B5=0,"",IFERROR(COUNTIFS(Export!$E:$E,A5,Export!$H:$H,"Efectivo",Export!$M:$M,"<="&11)/B5*100,0)) -> 12.5 | P5: =IF(B5=0,"",IFERROR(COUNTIFS(Export!$E:$E,A5,Export!$H:$H,"Efectivo",Export!$M:$M,"<="&12)/B5*100,0)) -> 12.5 | Q5: =IF(B5=0,"",IFERROR(COUNTIFS(Export!$E:$E,A5,Export!$H:$H,"Efectivo",Export!$M:$M,"<="&13)/B5*100,0)) -> 25 | R5: =IF(B5=0,"",IFERROR(COUNTIFS(Export!$E:$E,A5,Export!$H:$H,"Efectivo",Export!$M:$M,"<="&14)/B5*100,0)) -> 25 | S5: =IF(B5=0,"",IFERROR(COUNTIFS(Export!$E:$E,A5,Export!$H:$H,"Efectivo",Export!$M:$M,"<="&15)/B5*100,0)) -> 31.25 | T5: =IF(B5=0,"",IFERROR(COUNTIFS(Export!$E:$E,A5,Export!$H:$H,"Efectivo",Export!$M:$M,"<="&16)/B5*100,0)) -> 37.5 | U5: =IF(B5=0,"",IFERROR(COUNTIFS(Export!$E:$E,A5,Export!$H:$H,"Efectivo",Export!$M:$M,"<="&17)/B5*100,0)) -> 37.5 | V5: =IF(B5=0,"",IFERROR(COUNTIFS(Export!$E:$E,A5,Export!$H:$H,"Efectivo",Export!$M:$M,"<="&18)/B5*100,0)) -> 37.5 | W5: =IF(B5=0,"",IFERROR(COUNTIFS(Export!$E:$E,A5,Export!$H:$H,"Efectivo",Export!$M:$M,"<="&19)/B5*100,0)) -> 37.5 | X5: =IF(B5=0,"",IFERROR(COUNTIFS(Export!$E:$E,A5,Export!$H:$H,"Efectivo",Export!$M:$M,"<="&20)/B5*100,0)) -> 37.5 | Y5: =IF(B5=0,"",IFERROR(COUNTIFS(Export!$E:$E,A5,Export!$H:$H,"Efectivo",Export!$M:$M,"<="&21)/B5*100,0)) -> 37.5 | Z5: =IF(B5=0,"",IFERROR(COUNTIFS(Export!$E:$E,A5,Export!$H:$H,"Efectivo",Export!$M:$M,"<="&22)/B5*100,0)) -> 62.5 | AA5: =IF(B5=0,"",IFERROR(COUNTIFS(Export!$E:$E,A5,Export!$H:$H,"Efectivo",Export!$M:$M,"<="&23)/B5*100,0)) -> 62.5 | AB5: =IF(B5=0,"",IFERROR(COUNTIFS(Export!$E:$E,A5,Export!$H:$H,"Efectivo",Export!$M:$M,"<="&24)/B5*100,0)) -> 75 | AC5: =IF(B5=0,"",IFERROR(COUNTIFS(Export!$E:$E,A5,Export!$H:$H,"Efectivo",Export!$M:$M,"<="&25)/B5*100,0)) -> 87.5 | AD5: =IF(B5=0,"",IFERROR(COUNTIFS(Export!$E:$E,A5,Export!$H:$H,"Efectivo",Export!$M:$M,"<="&26)/B5*100,0)) -> 93.75 | AE5: =IF(B5=0,"",IFERROR(COUNTIFS(Export!$E:$E,A5,Export!$H:$H,"Efectivo",Export!$M:$M,"<="&27)/B5*100,0)) -> 93.75 | AF5: =IF(B5=0,"",IFERROR(COUNTIFS(Export!$E:$E,A5,Export!$H:$H,"Efectivo",Export!$M:$M,"<="&28)/B5*100,0)) -> 93.75 | AG5: =IF(B5=0,"",IFERROR(COUNTIFS(Export!$E:$E,A5,Export!$H:$H,"Efectivo",Export!$M:$M,"<="&29)/B5*100,0)) -> 93.75 | AH5: =IF(B5=0,"",IFERROR(COUNTIFS(Export!$E:$E,A5,Export!$H:$H,"Efectivo",Export!$M:$M,"<="&30)/B5*100,0)) -> 93.75 | AI5: =IF(B5=0,"",IFERROR(COUNTIFS(Export!$E:$E,A5,Export!$H:$H,"Efectivo",Export!$M:$M,"<="&31)/B5*100,0)) -> 93.75 | AJ5: =IF(B5=0,"",IFERROR(COUNTIFS(Export!$E:$E,A5,Export!$H:$H,"Efectivo",Export!$M:$M,"<="&32)/B5*100,0)) -> 93.75 | AK5: =IF(B5=0,"",IFERROR(COUNTIFS(Export!$E:$E,A5,Export!$H:$H,"Efectivo",Export!$M:$M,"<="&33)/B5*100,0)) -> 93.75 | AL5: =IF(B5=0,"",IFERROR(COUNTIFS(Export!$E:$E,A5,Export!$H:$H,"Efectivo",Export!$M:$M,"<="&34)/B5*100,0)) -> 93.75 | AM5: =IF(B5=0,"",IFERROR(COUNTIFS(Export!$E:$E,A5,Export!$H:$H,"Efectivo",Export!$M:$M,"<="&35)/B5*100,0)) -> 93.75 | AN5: =IF(B5=0,"",IFERROR(COUNTIFS(Export!$E:$E,A5,Export!$H:$H,"Efectivo",Export!$M:$M,"<="&36)/B5*100,0)) -> 93.75
A6: 04-2024 | B6: =IFERROR(COUNTIF(Export!$E:$E,A6),0) -> 18 | C6: =IFERROR(VLOOKUP(A6,Originaciones!$A:$B,2,0),"") -> 73 | D6: =IF(B6=0,"",IFERROR(COUNTIFS(Export!$E:$E,A6,Export!$H:$H,"Efectivo",Export!$M:$M,"<="&0)/B6*100,0)) -> 0 | E6: =IF(B6=0,"",IFERROR(COUNTIFS(Export!$E:$E,A6,Export!$H:$H,"Efectivo",Export!$M:$M,"<="&1)/B6*100,0)) -> 0 | F6: =IF(B6=0,"",IFERROR(COUNTIFS(Export!$E:$E,A6,Export!$H:$H,"Efectivo",Export!$M:$M,"<="&2)/B6*100,0)) -> 0 | G6: =IF(B6=0,"",IFERROR(COUNTIFS(Export!$E:$E,A6,Export!$H:$H,"Efectivo",Export!$M:$M,"<="&3)/B6*100,0)) -> 0 | H6: =IF(B6=0,"",IFERROR(COUNTIFS(Export!$E:$E,A6,Export!$H:$H,"Efectivo",Export!$M:$M,"<="&4)/B6*100,0)) -> 0 | I6: =IF(B6=0,"",IFERROR(COUNTIFS(Export!$E:$E,A6,Export!$H:$H,"Efectivo",Export!$M:$M,"<="&5)/B6*100,0)) -> 0 | J6: =IF(B6=0,"",IFERROR(COUNTIFS(Export!$E:$E,A6,Export!$H:$H,"Efectivo",Export!$M:$M,"<="&6)/B6*100,0)) -> 0 | K6: =IF(B6=0,"",IFERROR(COUNTIFS(Export!$E:$E,A6,Export!$H:$H,"Efectivo",Export!$M:$M,"<="&7)/B6*100,0)) -> 0 | L6: =IF(B6=0,"",IFERROR(COUNTIFS(Export!$E:$E,A6,Export!$H:$H,"Efectivo",Export!$M:$M,"<="&8)/B6*100,0)) -> 0 | M6: =IF(B6=0,"",IFERROR(COUNTIFS(Export!$E:$E,A6,Export!$H:$H,"Efectivo",Export!$M:$M,"<="&9)/B6*100,0)) -> 11.111111 | N6: =IF(B6=0,"",IFERROR(COUNTIFS(Export!$E:$E,A6,Export!$H:$H,"Efectivo",Export!$M:$M,"<="&10)/B6*100,0)) -> 16.666667 | O6: =IF(B6=0,"",IFERROR(COUNTIFS(Export!$E:$E,A6,Export!$H:$H,"Efectivo",Export!$M:$M,"<="&11)/B6*100,0)) -> 16.666667 | P6: =IF(B6=0,"",IFERROR(COUNTIFS(Export!$E:$E,A6,Export!$H:$H,"Efectivo",Export!$M:$M,"<="&12)/B6*100,0)) -> 16.666667 | Q6: =IF(B6=0,"",IFERROR(COUNTIFS(Export!$E:$E,A6,Export!$H:$H,"Efectivo",Export!$M:$M,"<="&13)/B6*100,0)) -> 22.222222 | R6: =IF(B6=0,"",IFERROR(COUNTIFS(Export!$E:$E,A6,Export!$H:$H,"Efectivo",Export!$M:$M,"<="&14)/B6*100,0)) -> 22.222222 | S6: =IF(B6=0,"",IFERROR(COUNTIFS(Export!$E:$E,A6,Export!$H:$H,"Efectivo",Export!$M:$M,"<="&15)/B6*100,0)) -> 33.333333 | T6: =IF(B6=0,"",IFERROR(COUNTIFS(Export!$E:$E,A6,Export!$H:$H,"Efectivo",Export!$M:$M,"<="&16)/B6*100,0)) -> 33.333333 | U6: =IF(B6=0,"",IFERROR(COUNTIFS(Export!$E:$E,A6,Export!$H:$H,"Efectivo",Export!$M:$M,"<="&17)/B6*100,0)) -> 33.333333 | V6: =IF(B6=0,"",IFERROR(COUNTIFS(Export!$E:$E,A6,Export!$H:$H,"Efectivo",Export!$M:$M,"<="&18)/B6*100,0)) -> 33.333333 | W6: =IF(B6=0,"",IFERROR(COUNTIFS(Export!$E:$E,A6,Export!$H:$H,"Efectivo",Export!$M:$M,"<="&19)/B6*100,0)) -> 38.888889 | X6: =IF(B6=0,"",IFERROR(COUNTIFS(Export!$E:$E,A6,Export!$H:$H,"Efectivo",Export!$M:$M,"<="&20)/B6*100,0)) -> 38.888889 | Y6: =IF(B6=0,"",IFERROR(COUNTIFS(Export!$E:$E,A6,Export!$H:$H,"Efectivo",Export!$M:$M,"<="&21)/B6*100,0)) -> 38.888889 | Z6: =IF(B6=0,"",IFERROR(COUNTIFS(Export!$E:$E,A6,Export!$H:$H,"Efectivo",Export!$M:$M,"<="&22)/B6*100,0)) -> 50 | AA6: =IF(B6=0,"",IFERROR(COUNTIFS(Export!$E:$E,A6,Export!$H:$H,"Efectivo",Export!$M:$M,"<="&23)/B6*100,0)) -> 61.111111 | AB6: =IF(B6=0,"",IFERROR(COUNTIFS(Export!$E:$E,A6,Export!$H:$H,"Efectivo",Export!$M:$M,"<="&24)/B6*100,0)) -> 61.111111 | AC6: =IF(B6=0,"",IFERROR(COUNTIFS(Export!$E:$E,A6,Export!$H:$H,"Efectivo",Export!$M:$M,"<="&25)/B6*100,0)) -> 61.111111 | AD6: =IF(B6=0,"",IFERROR(COUNTIFS(Export!$E:$E,A6,Export!$H:$H,"Efectivo",Export!$M:$M,"<="&26)/B6*100,0)) -> 61.111111 | AE6: =IF(B6=0,"",IFERROR(COUNTIFS(Export!$E:$E,A6,Export!$H:$H,"Efectivo",Export!$M:$M,"<="&27)/B6*100,0)) -> 61.111111 | AF6: =IF(B6=0,"",IFERROR(COUNTIFS(Export!$E:$E,A6,Export!$H:$H,"Efectivo",Export!$M:$M,"<="&28)/B6*100,0)) -> 61.111111 | AG6: =IF(B6=0,"",IFERROR(COUNTIFS(Export!$E:$E,A6,Export!$H:$H,"Efectivo",Export!$M:$M,"<="&29)/B6*100,0)) -> 61.111111 | AH6: =IF(B6=0,"",IFERROR(COUNTIFS(Export!$E:$E,A6,Export!$H:$H,"Efectivo",Export!$M:$M,"<="&30)/B6*100,0)) -> 61.111111 | AI6: =IF(B6=0,"",IFERROR(COUNTIFS(Export!$E:$E,A6,Export!$H:$H,"Efectivo",Export!$M:$M,"<="&31)/B6*100,0)) -> 61.111111 | AJ6: =IF(B6=0,"",IFERROR(COUNTIFS(Export!$E:$E,A6,Export!$H:$H,"Efectivo",Export!$M:$M,"<="&32)/B6*100,0)) -> 61.111111 | AK6: =IF(B6=0,"",IFERROR(COUNTIFS(Export!$E:$E,A6,Export!$H:$H,"Efectivo",Export!$M:$M,"<="&33)/B6*100,0)) -> 61.111111 | AL6: =IF(B6=0,"",IFERROR(COUNTIFS(Export!$E:$E,A6,Export!$H:$H,"Efectivo",Export!$M:$M,"<="&34)/B6*100,0)) -> 61.111111 | AM6: =IF(B6=0,"",IFERROR(COUNTIFS(Export!$E:$E,A6,Export!$H:$H,"Efectivo",Export!$M:$M,"<="&35)/B6*100,0)) -> 61.111111 | AN6: =IF(B6=0,"",IFERROR(COUNTIFS(Export!$E:$E,A6,Export!$H:$H,"Efectivo",Export!$M:$M,"<="&36)/B6*100,0)) -> 61.111111
A7: 05-2024 | B7: =IFERROR(COUNTIF(Export!$E:$E,A7),0) -> 21 | C7: =IFERROR(VLOOKUP(A7,Originaciones!$A:$B,2,0),"") -> 94 | D7: =IF(B7=0,"",IFERROR(COUNTIFS(Export!$E:$E,A7,Export!$H:$H,"Efectivo",Export!$M:$M,"<="&0)/B7*100,0)) -> 0 | E7: =IF(B7=0,"",IFERROR(COUNTIFS(Export!$E:$E,A7,Export!$H:$H,"Efectivo",Export!$M:$M,"<="&1)/B7*100,0)) -> 0 | F7: =IF(B7=0,"",IFERROR(COUNTIFS(Export!$E:$E,A7,Export!$H:$H,"Efectivo",Export!$M:$M,"<="&2)/B7*100,0)) -> 0 | G7: =IF(B7=0,"",IFERROR(COUNTIFS(Export!$E:$E,A7,Export!$H:$H,"Efectivo",Export!$M:$M,"<="&3)/B7*100,0)) -> 0 | H7: =IF(B7=0,"",IFERROR(COUNTIFS(Export!$E:$E,A7,Export!$H:$H,"Efectivo",Export!$M:$M,"<="&4)/B7*100,0)) -> 0 | I7: =IF(B7=0,"",IFERROR(COUNTIFS(Export!$E:$E,A7,Export!$H:$H,"Efectivo",Export!$M:$M,"<="&5)/B7*100,0)) -> 0 | J7: =IF(B7=0,"",IFERROR(COUNTIFS(Export!$E:$E,A7,Export!$H:$H,"Efectivo",Export!$M:$M,"<="&6)/B7*100,0)) -> 0 | K7: =IF(B7=0,"",IFERROR(COUNTIFS(Export!$E:$E,A7,Export!$H:$H,"Efectivo",Export!$M:$M,"<="&7)/B7*100,0)) -> 0 | L7: =IF(B7=0,"",IFERROR(COUNTIFS(Export!$E:$E,A7,Export!$H:$H,"Efectivo",Export!$M:$M,"<="&8)/B7*100,0)) -> 0 | M7: =IF(B7=0,"",IFERROR(COUNTIFS(Export!$E:$E,A7,Export!$H:$H,"Efectivo",Export!$M:$M,"<="&9)/B7*100,0)) -> 0 | N7: =IF(B7=0,"",IFERROR(COUNTIFS(Export!$E:$E,A7,Export!$H:$H,"Efectivo",Export!$M:$M,"<="&10)/B7*100,0)) -> 0 | O7: =IF(B7=0,"",IFERROR(COUNTIFS(Export!$E:$E,A7,Export!$H:$H,"Efectivo",Export!$M:$M,"<="&11)/B7*100,0)) -> 9.5238095 | P7: =IF(B7=0,"",IFERROR(COUNTIFS(Export!$E:$E,A7,Export!$H:$H,"Efectivo",Export!$M:$M,"<="&12)/B7*100,0)) -> 9.5238095 | Q7: =IF(B7=0,"",IFERROR(COUNTIFS(Export!$E:$E,A7,Export!$H:$H,"Efectivo",Export!$M:$M,"<="&13)/B7*100,0)) -> 14.285714 | R7: =IF(B7=0,"",IFERROR(COUNTIFS(Export!$E:$E,A7,Export!$H:$H,"Efectivo",Export!$M:$M,"<="&14)/B7*100,0)) -> 19.047619 | S7: =IF(B7=0,"",IFERROR(COUNTIFS(Export!$E:$E,A7,Export!$H:$H,"Efectivo",Export!$M:$M,"<="&15)/B7*100,0)) -> 23.809524 | T7: =IF(B7=0,"",IFERROR(COUNTIFS(Export!$E:$E,A7,Export!$H:$H,"Efectivo",Export!$M:$M,"<="&16)/B7*100,0)) -> 23.809524 | U7: =IF(B7=0,"",IFERROR(COUNTIFS(Export!$E:$E,A7,Export!$H:$H,"Efectivo",Export!$M:$M,"<="&17)/B7*100,0)) -> 28.571429 | V7: =IF(B7=0,"",IFERROR(COUNTIFS(Export!$E:$E,A7,Export!$H:$H,"Efectivo",Export!$M:$M,"<="&18)/B7*100,0)) -> 28.571429 | W7: =IF(B7=0,"",IFERROR(COUNTIFS(Export!$E:$E,A7,Export!$H:$H,"Efectivo",Export!$M:$M,"<="&19)/B7*100,0)) -> 28.571429 | X7: =IF(B7=0,"",IFERROR(COUNTIFS(Export!$E:$E,A7,Export!$H:$H,"Efectivo",Export!$M:$M,"<="&20)/B7*100,0)) -> 38.095238 | Y7: =IF(B7=0,"",IFERROR(COUNTIFS(Export!$E:$E,A7,Export!$H:$H,"Efectivo",Export!$M:$M,"<="&21)/B7*100,0)) -> 52.380952 | Z7: =IF(B7=0,"",IFERROR(COUNTIFS(Export!$E:$E,A7,Export!$H:$H,"Efectivo",Export!$M:$M,"<="&22)/B7*100,0)) -> 61.904762 | AA7: =IF(B7=0,"",IFERROR(COUNTIFS(Export!$E:$E,A7,Export!$H:$H,"Efectivo",Export!$M:$M,"<="&23)/B7*100,0)) -> 71.428571 | AB7: =IF(B7=0,"",IFERROR(COUNTIFS(Export!$E:$E,A7,Export!$H:$H,"Efectivo",Export!$M:$M,"<="&24)/B7*100,0)) -> 71.428571 | AC7: =IF(B7=0,"",IFERROR(COUNTIFS(Export!$E:$E,A7,Export!$H:$H,"Efectivo",Export!$M:$M,"<="&25)/B7*100,0)) -> 71.428571 | AD7: =IF(B7=0,"",IFERROR(COUNTIFS(Export!$E:$E,A7,Export!$H:$H,"Efectivo",Export!$M:$M,"<="&26)/B7*100,0)) -> 71.428571 | AE7: =IF(B7=0,"",IFERROR(COUNTIFS(Export!$E:$E,A7,Export!$H:$H,"Efectivo",Export!$M:$M,"<="&27)/B7*100,0)) -> 71.428571 | AF7: =IF(B7=0,"",IFERROR(COUNTIFS(Export!$E:$E,A7,Export!$H:$H,"Efectivo",Export!$M:$M,"<="&28)/B7*100,0)) -> 71.428571 | AG7: =IF(B7=0,"",IFERROR(COUNTIFS(Export!$E:$E,A7,Export!$H:$H,"Efectivo",Export!$M:$M,"<="&29)/B7*100,0)) -> 71.428571 | AH7: =IF(B7=0,"",IFERROR(COUNTIFS(Export!$E:$E,A7,Export!$H:$H,"Efectivo",Export!$M:$M,"<="&30)/B7*100,0)) -> 71.428571 | AI7: =IF(B7=0,"",IFERROR(COUNTIFS(Export!$E:$E,A7,Export!$H:$H,"Efectivo",Export!$M:$M,"<="&31)/B7*100,0)) -> 71.428571 | AJ7: =IF(B7=0,"",IFERROR(COUNTIFS(Export!$E:$E,A7,Export!$H:$H,"Efectivo",Export!$M:$M,"<="&32)/B7*100,0)) -> 71.428571 | AK7: =IF(B7=0,"",IFERROR(COUNTIFS(Export!$E:$E,A7,Export!$H:$H,"Efectivo",Export!$M:$M,"<="&33)/B7*100,0)) -> 71.428571 | AL7: =IF(B7=0,"",IFERROR(COUNTIFS(Export!$E:$E,A7,Export!$H:$H,"Efectivo",Export!$M:$M,"<="&34)/B7*100,0)) -> 71.428571 | AM7: =IF(B7=0,"",IFERROR(COUNTIFS(Export!$E:$E,A7,Export!$H:$H,"Efectivo",Export!$M:$M,"<="&35)/B7*100,0)) -> 71.428571 | AN7: =IF(B7=0,"",IFERROR(COUNTIFS(Export!$E:$E,A7,Export!$H:$H,"Efectivo",Export!$M:$M,"<="&36)/B7*100,0)) -> 71.428571
A8: 06-2024 | B8: =IFERROR(COUNTIF(Export!$E:$E,A8),0) -> 20 | C8: =IFERROR(VLOOKUP(A8,Originaciones!$A:$B,2,0),"") -> 103 | D8: =IF(B8=0,"",IFERROR(COUNTIFS(Export!$E:$E,A8,Export!$H:$H,"Efectivo",Export!$M:$M,"<="&0)/B8*100,0)) -> 0 | E8: =IF(B8=0,"",IFERROR(COUNTIFS(Export!$E:$E,A8,Export!$H:$H,"Efectivo",Export!$M:$M,"<="&1)/B8*100,0)) -> 0 | F8: =IF(B8=0,"",IFERROR(COUNTIFS(Export!$E:$E,A8,Export!$H:$H,"Efectivo",Export!$M:$M,"<="&2)/B8*100,0)) -> 0 | G8: =IF(B8=0,"",IFERROR(COUNTIFS(Export!$E:$E,A8,Export!$H:$H,"Efectivo",Export!$M:$M,"<="&3)/B8*100,0)) -> 0 | H8: =IF(B8=0,"",IFERROR(COUNTIFS(Export!$E:$E,A8,Export!$H:$H,"Efectivo",Export!$M:$M,"<="&4)/B8*100,0)) -> 0 | I8: =IF(B8=0,"",IFERROR(COUNTIFS(Export!$E:$E,A8,Export!$H:$H,"Efectivo",Export!$M:$M,"<="&5)/B8*100,0)) -> 0 | J8: =IF(B8=0,"",IFERROR(COUNTIFS(Export!$E:$E,A8,Export!$H:$H,"Efectivo",Export!$M:$M,"<="&6)/B8*100,0)) -> 0 | K8: =IF(B8=0,"",IFERROR(COUNTIFS(Export!$E:$E,A8,Export!$H:$H,"Efectivo",Export!$M:$M,"<="&7)/B8*100,0)) -> 0 | L8: =IF(B8=0,"",IFERROR(COUNTIFS(Export!$E:$E,A8,Export!$H:$H,"Efectivo",Export!$M:$M,"<="&8)/B8*100,0)) -> 0 | M8: =IF(B8=0,"",IFERROR(COUNTIFS(Export!$E:$E,A8,Export!$H:$H,"Efectivo",Export!$M:$M,"<="&9)/B8*100,0)) -> 15 | N8: =IF(B8=0,"",IFERROR(COUNTIFS(Export!$E:$E,A8,Export!$H:$H,"Efectivo",Export!$M:$M,"<="&10)/B8*100,0)) -> 25 | O8: =IF(B8=0,"",IFERROR(COUNTIFS(Export!$E:$E,A8,Export!$H:$H,"Efectivo",Export!$M:$M,"<="&11)/B8*100,0)) -> 30 | P8: =IF(B8=0,"",IFERROR(COUNTIFS(Export!$E:$E,A8,Export!$H:$H,"Efectivo",Export!$M:$M,"<="&12)/B8*100,0)) -> 35 | Q8: =IF(B8=0,"",IFERROR(COUNTIFS(Export!$E:$E,A8,Export!$H:$H,"Efectivo",Export!$M:$M,"<="&13)/B8*100,0)) -> 40 | R8: =IF(B8=0,"",IFERROR(COUNTIFS(Export!$E:$E,A8,Export!$H:$H,"Efectivo",Export!$M:$M,"<="&14)/B8*100,0)) -> 55 | S8: =IF(B8=0,"",IFERROR(COUNTIFS(Export!$E:$E,A8,Export!$H:$H,"Efectivo",Export!$M:$M,"<="&15)/B8*100,0)) -> 55 | T8: =IF(B8=0,"",IFERROR(COUNTIFS(Export!$E:$E,A8,Export!$H:$H,"Efectivo",Export!$M:$M,"<="&16)/B8*100,0)) -> 55 | U8: =IF(B8=0,"",IFERROR(COUNTIFS(Export!$E:$E,A8,Export!$H:$H,"Efectivo",Export!$M:$M,"<="&17)/B8*100,0)) -> 55 | V8: =IF(B8=0,"",IFERROR(COUNTIFS(Export!$E:$E,A8,Export!$H:$H,"Efectivo",Export!$M:$M,"<="&18)/B8*100,0)) -> 60 | W8: =IF(B8=0,"",IFERROR(COUNTIFS(Export!$E:$E,A8,Export!$H:$H,"Efectivo",Export!$M:$M,"<="&19)/B8*100,0)) -> 60 | X8: =IF(B8=0,"",IFERROR(COUNTIFS(Export!$E:$E,A8,Export!$H:$H,"Efectivo",Export!$M:$M,"<="&20)/B8*100,0)) -> 70 | Y8: =IF(B8=0,"",IFERROR(COUNTIFS(Export!$E:$E,A8,Export!$H:$H,"Efectivo",Export!$M:$M,"<="&21)/B8*100,0)) -> 75 | Z8: =IF(B8=0,"",IFERROR(COUNTIFS(Export!$E:$E,A8,Export!$H:$H,"Efectivo",Export!$M:$M,"<="&22)/B8*100,0)) -> 85 | AA8: =IF(B8=0,"",IFERROR(COUNTIFS(Export!$E:$E,A8,Export!$H:$H,"Efectivo",Export!$M:$M,"<="&23)/B8*100,0)) -> 90 | AB8: =IF(B8=0,"",IFERROR(COUNTIFS(Export!$E:$E,A8,Export!$H:$H,"Efectivo",Export!$M:$M,"<="&24)/B8*100,0)) -> 90 | AC8: =IF(B8=0,"",IFERROR(COUNTIFS(Export!$E:$E,A8,Export!$H:$H,"Efectivo",Export!$M:$M,"<="&25)/B8*100,0)) -> 90 | AD8: =IF(B8=0,"",IFERROR(COUNTIFS(Export!$E:$E,A8,Export!$H:$H,"Efectivo",Export!$M:$M,"<="&26)/B8*100,0)) -> 90 | AE8: =IF(B8=0,"",IFERROR(COUNTIFS(Export!$E:$E,A8,Export!$H:$H,"Efectivo",Export!$M:$M,"<="&27)/B8*100,0)) -> 90 | AF8: =IF(B8=0,"",IFERROR(COUNTIFS(Export!$E:$E,A8,Export!$H:$H,"Efectivo",Export!$M:$M,"<="&28)/B8*100,0)) -> 90 | AG8: =IF(B8=0,"",IFERROR(COUNTIFS(Export!$E:$E,A8,Export!$H:$H,"Efectivo",Export!$M:$M,"<="&29)/B8*100,0)) -> 90 | AH8: =IF(B8=0,"",IFERROR(COUNTIFS(Export!$E:$E,A8,Export!$H:$H,"Efectivo",Export!$M:$M,"<="&30)/B8*100,0)) -> 90 | AI8: =IF(B8=0,"",IFERROR(COUNTIFS(Export!$E:$E,A8,Export!$H:$H,"Efectivo",Export!$M:$M,"<="&31)/B8*100,0)) -> 90 | AJ8: =IF(B8=0,"",IFERROR(COUNTIFS(Export!$E:$E,A8,Export!$H:$H,"Efectivo",Export!$M:$M,"<="&32)/B8*100,0)) -> 90 | AK8: =IF(B8=0,"",IFERROR(COUNTIFS(Export!$E:$E,A8,Export!$H:$H,"Efectivo",Export!$M:$M,"<="&33)/B8*100,0)) -> 90 | AL8: =IF(B8=0,"",IFERROR(COUNTIFS(Export!$E:$E,A8,Export!$H:$H,"Efectivo",Export!$M:$M,"<="&34)/B8*100,0)) -> 90 | AM8: =IF(B8=0,"",IFERROR(COUNTIFS(Export!$E:$E,A8,Export!$H:$H,"Efectivo",Export!$M:$M,"<="&35)/B8*100,0)) -> 90 | AN8: =IF(B8=0,"",IFERROR(COUNTIFS(Export!$E:$E,A8,Export!$H:$H,"Efectivo",Export!$M:$M,"<="&36)/B8*100,0)) -> 90
A9: 07-2024 | B9: =IFERROR(COUNTIF(Export!$E:$E,A9),0) -> 39 | C9: =IFERROR(VLOOKUP(A9,Originaciones!$A:$B,2,0),"") -> 119 | D9: =IF(B9=0,"",IFERROR(COUNTIFS(Export!$E:$E,A9,Export!$H:$H,"Efectivo",Export!$M:$M,"<="&0)/B9*100,0)) -> 0 | E9: =IF(B9=0,"",IFERROR(COUNTIFS(Export!$E:$E,A9,Export!$H:$H,"Efectivo",Export!$M:$M,"<="&1)/B9*100,0)) -> 0 | F9: =IF(B9=0,"",IFERROR(COUNTIFS(Export!$E:$E,A9,Export!$H:$H,"Efectivo",Export!$M:$M,"<="&2)/B9*100,0)) -> 0 | G9: =IF(B9=0,"",IFERROR(COUNTIFS(Export!$E:$E,A9,Export!$H:$H,"Efectivo",Export!$M:$M,"<="&3)/B9*100,0)) -> 0 | H9: =IF(B9=0,"",IFERROR(COUNTIFS(Export!$E:$E,A9,Export!$H:$H,"Efectivo",Export!$M:$M,"<="&4)/B9*100,0)) -> 0 | I9: =IF(B9=0,"",IFERROR(COUNTIFS(Export!$E:$E,A9,Export!$H:$H,"Efectivo",Export!$M:$M,"<="&5)/B9*100,0)) -> 0 | J9: =IF(B9=0,"",IFERROR(COUNTIFS(Export!$E:$E,A9,Export!$H:$H,"Efectivo",Export!$M:$M,"<="&6)/B9*100,0)) -> 10.25641 | K9: =IF(B9=0,"",IFERROR(COUNTIFS(Export!$E:$E,A9,Export!$H:$H,"Efectivo",Export!$M:$M,"<="&7)/B9*100,0)) -> 10.25641 | L9: =IF(B9=0,"",IFERROR(COUNTIFS(Export!$E:$E,A9,Export!$H:$H,"Efectivo",Export!$M:$M,"<="&8)/B9*100,0)) -> 17.948718 | M9: =IF(B9=0,"",IFERROR(COUNTIFS(Export!$E:$E,A9,Export!$H:$H,"Efectivo",Export!$M:$M,"<="&9)/B9*100,0)) -> 23.076923 | N9: =IF(B9=0,"",IFERROR(COUNTIFS(Export!$E:$E,A9,Export!$H:$H,"Efectivo",Export!$M:$M,"<="&10)/B9*100,0)) -> 30.769231 | O9: =IF(B9=0,"",IFERROR(COUNTIFS(Export!$E:$E,A9,Export!$H:$H,"Efectivo",Export!$M:$M,"<="&11)/B9*100,0)) -> 33.333333 | P9: =IF(B9=0,"",IFERROR(COUNTIFS(Export!$E:$E,A9,Export!$H:$H,"Efectivo",Export!$M:$M,"<="&12)/B9*100,0)) -> 43.589744 | Q9: =IF(B9=0,"",IFERROR(COUNTIFS(Export!$E:$E,A9,Export!$H:$H,"Efectivo",Export!$M:$M,"<="&13)/B9*100,0)) -> 46.153846 | R9: =IF(B9=0,"",IFERROR(COUNTIFS(Export!$E:$E,A9,Export!$H:$H,"Efectivo",Export!$M:$M,"<="&14)/B9*100,0)) -> 46.153846 | S9: =IF(B9=0,"",IFERROR(COUNTIFS(Export!$E:$E,A9,Export!$H:$H,"Efectivo",Export!$M:$M,"<="&15)/B9*100,0)) -> 46.153846 | T9: =IF(B9=0,"",IFERROR(COUNTIFS(Export!$E:$E,A9,Export!$H:$H,"Efectivo",Export!$M:$M,"<="&16)/B9*100,0)) -> 48.717949 | U9: =IF(B9=0,"",IFERROR(COUNTIFS(Export!$E:$E,A9,Export!$H:$H,"Efectivo",Export!$M:$M,"<="&17)/B9*100,0)) -> 51.282051 | V9: =IF(B9=0,"",IFERROR(COUNTIFS(Export!$E:$E,A9,Export!$H:$H,"Efectivo",Export!$M:$M,"<="&18)/B9*100,0)) -> 56.410256 | W9: =IF(B9=0,"",IFERROR(COUNTIFS(Export!$E:$E,A9,Export!$H:$H,"Efectivo",Export!$M:$M,"<="&19)/B9*100,0)) -> 61.538462 | X9: =IF(B9=0,"",IFERROR(COUNTIFS(Export!$E:$E,A9,Export!$H:$H,"Efectivo",Export!$M:$M,"<="&20)/B9*100,0)) -> 64.102564 | Y9: =IF(B9=0,"",IFERROR(COUNTIFS(Export!$E:$E,A9,Export!$H:$H,"Efectivo",Export!$M:$M,"<="&21)/B9*100,0)) -> 71.794872 | Z9: =IF(B9=0,"",IFERROR(COUNTIFS(Export!$E:$E,A9,Export!$H:$H,"Efectivo",Export!$M:$M,"<="&22)/B9*100,0)) -> 71.794872 | AA9: =IF(B9=0,"",IFERROR(COUNTIFS(Export!$E:$E,A9,Export!$H:$H,"Efectivo",Export!$M:$M,"<="&23)/B9*100,0)) -> 71.794872 | AB9: =IF(B9=0,"",IFERROR(COUNTIFS(Export!$E:$E,A9,Export!$H:$H,"Efectivo",Export!$M:$M,"<="&24)/B9*100,0)) -> 71.794872 | AC9: =IF(B9=0,"",IFERROR(COUNTIFS(Export!$E:$E,A9,Export!$H:$H,"Efectivo",Export!$M:$M,"<="&25)/B9*100,0)) -> 71.794872 | AD9: =IF(B9=0,"",IFERROR(COUNTIFS(Export!$E:$E,A9,Export!$H:$H,"Efectivo",Export!$M:$M,"<="&26)/B9*100,0)) -> 71.794872 | AE9: =IF(B9=0,"",IFERROR(COUNTIFS(Export!$E:$E,A9,Export!$H:$H,"Efectivo",Export!$M:$M,"<="&27)/B9*100,0)) -> 71.794872 | AF9: =IF(B9=0,"",IFERROR(COUNTIFS(Export!$E:$E,A9,Export!$H:$H,"Efectivo",Export!$M:$M,"<="&28)/B9*100,0)) -> 71.794872 | AG9: =IF(B9=0,"",IFERROR(COUNTIFS(Export!$E:$E,A9,Export!$H:$H,"Efectivo",Export!$M:$M,"<="&29)/B9*100,0)) -> 71.794872 | AH9: =IF(B9=0,"",IFERROR(COUNTIFS(Export!$E:$E,A9,Export!$H:$H,"Efectivo",Export!$M:$M,"<="&30)/B9*100,0)) -> 71.794872 | AI9: =IF(B9=0,"",IFERROR(COUNTIFS(Export!$E:$E,A9,Export!$H:$H,"Efectivo",Export!$M:$M,"<="&31)/B9*100,0)) -> 71.794872 | AJ9: =IF(B9=0,"",IFERROR(COUNTIFS(Export!$E:$E,A9,Export!$H:$H,"Efectivo",Export!$M:$M,"<="&32)/B9*100,0)) -> 71.794872 | AK9: =IF(B9=0,"",IFERROR(COUNTIFS(Export!$E:$E,A9,Export!$H:$H,"Efectivo",Export!$M:$M,"<="&33)/B9*100,0)) -> 71.794872 | AL9: =IF(B9=0,"",IFERROR(COUNTIFS(Export!$E:$E,A9,Export!$H:$H,"Efectivo",Export!$M:$M,"<="&34)/B9*100,0)) -> 71.794872 | AM9: =IF(B9=0,"",IFERROR(COUNTIFS(Export!$E:$E,A9,Export!$H:$H,"Efectivo",Export!$M:$M,"<="&35)/B9*100,0)) -> 71.794872 | AN9: =IF(B9=0,"",IFERROR(COUNTIFS(Export!$E:$E,A9,Export!$H:$H,"Efectivo",Export!$M:$M,"<="&36)/B9*100,0)) -> 71.794872
A10: 08-2024 | B10: =IFERROR(COUNTIF(Export!$E:$E,A10),0) -> 41 | C10: =IFERROR(VLOOKUP(A10,Originaciones!$A:$B,2,0),"") -> 114 | D10: =IF(B10=0,"",IFERROR(COUNTIFS(Export!$E:$E,A10,Export!$H:$H,"Efectivo",Export!$M:$M,"<="&0)/B10*100,0)) -> 0 | E10: =IF(B10=0,"",IFERROR(COUNTIFS(Export!$E:$E,A10,Export!$H:$H,"Efectivo",Export!$M:$M,"<="&1)/B10*100,0)) -> 0 | F10: =IF(B10=0,"",IFERROR(COUNTIFS(Export!$E:$E,A10,Export!$H:$H,"Efectivo",Export!$M:$M,"<="&2)/B10*100,0)) -> 0 | G10: =IF(B10=0,"",IFERROR(COUNTIFS(Export!$E:$E,A10,Export!$H:$H,"Efectivo",Export!$M:$M,"<="&3)/B10*100,0)) -> 0 | H10: =IF(B10=0,"",IFERROR(COUNTIFS(Export!$E:$E,A10,Export!$H:$H,"Efectivo",Export!$M:$M,"<="&4)/B10*100,0)) -> 0 | I10: =IF(B10=0,"",IFERROR(COUNTIFS(Export!$E:$E,A10,Export!$H:$H,"Efectivo",Export!$M:$M,"<="&5)/B10*100,0)) -> 4.8780488 | J10: =IF(B10=0,"",IFERROR(COUNTIFS(Export!$E:$E,A10,Export!$H:$H,"Efectivo",Export!$M:$M,"<="&6)/B10*100,0)) -> 4.8780488 | K10: =IF(B10=0,"",IFERROR(COUNTIFS(Export!$E:$E,A10,Export!$H:$H,"Efectivo",Export!$M:$M,"<="&7)/B10*100,0)) -> 14.634146 | L10: =IF(B10=0,"",IFERROR(COUNTIFS(Export!$E:$E,A10,Export!$H:$H,"Efectivo",Export!$M:$M,"<="&8)/B10*100,0)) -> 24.390244 | M10: =IF(B10=0,"",IFERROR(COUNTIFS(Export!$E:$E,A10,Export!$H:$H,"Efectivo",Export!$M:$M,"<="&9)/B10*100,0)) -> 31.707317 | N10: =IF(B10=0,"",IFERROR(COUNTIFS(Export!$E:$E,A10,Export!$H:$H,"Efectivo",Export!$M:$M,"<="&10)/B10*100,0)) -> 43.902439 | O10: =IF(B10=0,"",IFERROR(COUNTIFS(Export!$E:$E,A10,Export!$H:$H,"Efectivo",Export!$M:$M,"<="&11)/B10*100,0)) -> 51.219512 | P10: =IF(B10=0,"",IFERROR(COUNTIFS(Export!$E:$E,A10,Export!$H:$H,"Efectivo",Export!$M:$M,"<="&12)/B10*100,0)) -> 56.097561 | Q10: =IF(B10=0,"",IFERROR(COUNTIFS(Export!$E:$E,A10,Export!$H:$H,"Efectivo",Export!$M:$M,"<="&13)/B10*100,0)) -> 60.97561 | R10: =IF(B10=0,"",IFERROR(COUNTIFS(Export!$E:$E,A10,Export!$H:$H,"Efectivo",Export!$M:$M,"<="&14)/B10*100,0)) -> 63.414634 | S10: =IF(B10=0,"",IFERROR(COUNTIFS(Export!$E:$E,A10,Export!$H:$H,"Efectivo",Export!$M:$M,"<="&15)/B10*100,0)) -> 63.414634 | T10: =IF(B10=0,"",IFERROR(COUNTIFS(Export!$E:$E,A10,Export!$H:$H,"Efectivo",Export!$M:$M,"<="&16)/B10*100,0)) -> 65.853659 | U10: =IF(B10=0,"",IFERROR(COUNTIFS(Export!$E:$E,A10,Export!$H:$H,"Efectivo",Export!$M:$M,"<="&17)/B10*100,0)) -> 65.853659 | V10: =IF(B10=0,"",IFERROR(COUNTIFS(Export!$E:$E,A10,Export!$H:$H,"Efectivo",Export!$M:$M,"<="&18)/B10*100,0)) -> 73.170732 | W10: =IF(B10=0,"",IFERROR(COUNTIFS(Export!$E:$E,A10,Export!$H:$H,"Efectivo",Export!$M:$M,"<="&19)/B10*100,0)) -> 78.04878 | X10: =IF(B10=0,"",IFERROR(COUNTIFS(Export!$E:$E,A10,Export!$H:$H,"Efectivo",Export!$M:$M,"<="&20)/B10*100,0)) -> 82.926829 | Y10: =IF(B10=0,"",IFERROR(COUNTIFS(Export!$E:$E,A10,Export!$H:$H,"Efectivo",Export!$M:$M,"<="&21)/B10*100,0)) -> 82.926829 | Z10: =IF(B10=0,"",IFERROR(COUNTIFS(Export!$E:$E,A10,Export!$H:$H,"Efectivo",Export!$M:$M,"<="&22)/B10*100,0)) -> 82.926829 | AA10: =IF(B10=0,"",IFERROR(COUNTIFS(Export!$E:$E,A10,Export!$H:$H,"Efectivo",Export!$M:$M,"<="&23)/B10*100,0)) -> 82.926829 | AB10: =IF(B10=0,"",IFERROR(COUNTIFS(Export!$E:$E,A10,Export!$H:$H,"Efectivo",Export!$M:$M,"<="&24)/B10*100,0)) -> 82.926829 | AC10: =IF(B10=0,"",IFERROR(COUNTIFS(Export!$E:$E,A10,Export!$H:$H,"Efectivo",Export!$M:$M,"<="&25)/B10*100,0)) -> 82.926829 | AD10: =IF(B10=0,"",IFERROR(COUNTIFS(Export!$E:$E,A10,Export!$H:$H,"Efectivo",Export!$M:$M,"<="&26)/B10*100,0)) -> 82.926829 | AE10: =IF(B10=0,"",IFERROR(COUNTIFS(Export!$E:$E,A10,Export!$H:$H,"Efectivo",Export!$M:$M,"<="&27)/B10*100,0)) -> 82.926829 | AF10: =IF(B10=0,"",IFERROR(COUNTIFS(Export!$E:$E,A10,Export!$H:$H,"Efectivo",Export!$M:$M,"<="&28)/B10*100,0)) -> 82.926829 | AG10: =IF(B10=0,"",IFERROR(COUNTIFS(Export!$E:$E,A10,Export!$H:$H,"Efectivo",Export!$M:$M,"<="&29)/B10*100,0)) -> 82.926829 | AH10: =IF(B10=0,"",IFERROR(COUNTIFS(Export!$E:$E,A10,Export!$H:$H,"Efectivo",Export!$M:$M,"<="&30)/B10*100,0)) -> 82.926829 | AI10: =IF(B10=0,"",IFERROR(COUNTIFS(Export!$E:$E,A10,Export!$H:$H,"Efectivo",Export!$M:$M,"<="&31)/B10*100,0)) -> 82.926829 | AJ10: =IF(B10=0,"",IFERROR(COUNTIFS(Export!$E:$E,A10,Export!$H:$H,"Efectivo",Export!$M:$M,"<="&32)/B10*100,0)) -> 82.926829 | AK10: =IF(B10=0,"",IFERROR(COUNTIFS(Export!$E:$E,A10,Export!$H:$H,"Efectivo",Export!$M:$M,"<="&33)/B10*100,0)) -> 82.926829 | AL10: =IF(B10=0,"",IFERROR(COUNTIFS(Export!$E:$E,A10,Export!$H:$H,"Efectivo",Export!$M:$M,"<="&34)/B10*100,0)) -> 82.926829 | AM10: =IF(B10=0,"",IFERROR(COUNTIFS(Export!$E:$E,A10,Export!$H:$H,"Efectivo",Export!$M:$M,"<="&35)/B10*100,0)) -> 82.926829 | AN10: =IF(B10=0,"",IFERROR(COUNTIFS(Export!$E:$E,A10,Export!$H:$H,"Efectivo",Export!$M:$M,"<="&36)/B10*100,0)) -> 82.926829
